Workbook

Sheet Faturado mensal
M1: =SUM(faturado[jan-25]) -> 3619127.4 | N1: =SUM(faturado[fev-25]) -> 4320391.3 | O1: =SUM(faturado[mar-25]) -> 3902344.3 | P1: =SUM(faturado[abr-25]) -> 3829344.8 | Q1: =SUM(faturado[mai-25]) -> 4132901.8 | R1: =SUM(faturado[jun-25]) -> 4141150.1 | S1: =SUM(faturado[jul-25]) -> 4286340.2 | T1: =SUM(faturado[ago-25]) -> 4032447.3 | U1: =SUM(faturado[set-25]) -> 5129442.6 | V1: =SUM(faturado[out-25]) -> 4946827.6 | W1: =SUM(faturado[nov-25]) -> 4434241.2 | X1: =SUM(faturado[dez-25]) -> 5035170.3 | Y1: =SUM(faturado[2025]) -> 55977647 | Z1: =SUM(faturado[jan-26]) -> 3634915.2 | AA1: =SUM(faturado[fev-26]) -> 4723958.9 | AB1: =SUM(faturado[mar-26]) -> 4291708.5 | AC1: =SUM(faturado[abr-26]) -> 4992439.9 | AD1: =SUM(faturado[mai-26]) -> 4845613.8 | AE1: =SUM(faturado[jun-26]) -> 3848780.6 | AF1: =SUM(faturado[jul-26]) -> 0 | AG1: =SUM(faturado[ago-26]) -> 0 | AH1: =SUM(faturado[set-26]) -> 0 | AI1: =SUM(faturado[out-26]) -> 0 | AJ1: =SUM(faturado[nov-26]) -> 0 | AK1: =SUM(faturado[dez-26]) -> 0 | AL1: =SUM(faturado[2026]) -> 26581067
A2: contrato | B2: pn_fornecedor | C2: descricao_fornecedor | D2: status_do_contrato | E2: departamento | F2: família | G2: gestão | H2: curva | I2: referencia_a | J2: descricao_condicao_de_pagamento | K2: depto_de_compras | L2: descricao_dpto_de_compras | M2: jan-25 | N2: fev-25 | O2: mar-25 | P2: abr-25 | Q2: mai-25 | R2: jun-25 | S2: jul-25 | T2: ago-25 | U2: set-25 | V2: out-25 | W2: nov-25 | X2: dez-25 | Y2: 2025 | Z2: jan-26 | AA2: fev-26 | AB2: mar-26 | AC2: abr-26 | AD2: mai-26 | AE2: jun-26 | AF2: jul-26 | AG2: ago-26 | AH2: set-26 | AI2: out-26 | AJ2: nov-26 | AK2: dez-26 | AL2: 2026
A3: CS0000647 | B3: 090030154 | C3: OPUS CONSULT TEC E EMPRESARIAL | D3: Concluído | G3: INDUSTRIAL SRS | H3: C | I3: OPUS CONSULT TEC E EMPRESARIAL | J3: 30 DIAS | K3: SRSFAB | L3: PRGM . COMPRAS - SRS - FABRICA | M3: =SUMIFS(#REF!,#REF!, $A3,#REF!, ">="&'Faturado mensal'!M$2,#REF!, "<"&EOMONTH('Faturado mensal'!M$2,0)) -> 0 | N3: =SUMIFS(#REF!,#REF!, $A3,#REF!, ">="&'Faturado mensal'!N$2,#REF!, "<"&EOMONTH('Faturado mensal'!N$2,0)) -> 0 | O3: =SUMIFS(#REF!,#REF!, $A3,#REF!, ">="&'Faturado mensal'!O$2,#REF!, "<"&EOMONTH('Faturado mensal'!O$2,0)) -> 0 | P3: =SUMIFS(#REF!,#REF!, $A3,#REF!, ">="&'Faturado mensal'!P$2,#REF!, "<"&EOMONTH('Faturado mensal'!P$2,0)) -> 0 | Q3: =SUMIFS(#REF!,#REF!, $A3,#REF!, ">="&'Faturado mensal'!Q$2,#REF!, "<"&EOMONTH('Faturado mensal'!Q$2,0)) -> 0 | R3: =SUMIFS(#REF!,#REF!, $A3,#REF!, ">="&'Faturado mensal'!R$2,#REF!, "<"&EOMONTH('Faturado mensal'!R$2,0)) -> 0 | S3: =SUMIFS(#REF!,#REF!, $A3,#REF!, ">="&'Faturado mensal'!S$2,#REF!, "<"&EOMONTH('Faturado mensal'!S$2,0)) -> 0 | T3: =SUMIFS(#REF!,#REF!, $A3,#REF!, ">="&'Faturado mensal'!T$2,#REF!, "<"&EOMONTH('Faturado mensal'!T$2,0)) -> 0 | ... X3: =SUMIFS(#REF!,#REF!, $A3,#REF!, ">="&'Faturado mensal'!X$2,#REF!, "<"&EOMONTH('Faturado mensal'!X$2,0)) -> 0 | Y3: =SUMIFS(#REF!,#REF!, $A3,#REF!, ">="&'Faturado mensal'!M$2,#REF!, "<"&EOMONTH('Faturado mensal'!M$2,12)) -> 0 | Z3: =SUMIFS(#REF!,#REF!, $A3,#REF!, ">="&'Faturado mensal'!Z$2,#REF!, "<"&EOMONTH('Faturado mensal'!Z$2,0)) -> 0 | AA3: =SUMIFS(#REF!,#REF!, $A3,#REF!, ">="&'Faturado mensal'!AA$2,#REF!, "<"&EOMONTH('Faturado mensal'!AA$2,0)) -> 0 | AB3: =SUMIFS(#REF!,#REF!, $A3,#REF!, ">="&'Faturado mensal'!AB$2,#REF!, "<"&EOMONTH('Faturado mensal'!AB$2,0)) -> 0 | AC3: =SUMIFS(#REF!,#REF!, $A3,#REF!, ">="&'Faturado mensal'!AC$2,#REF!, "<"&EOMONTH('Faturado mensal'!AC$2,0)) -> 0 | AD3: =SUMIFS(#REF!,#REF!, $A3,#REF!, ">="&'Faturado mensal'!AD$2,#REF!, "<"&EOMONTH('Faturado mensal'!AD$2,0)) -> 0 | AE3: =SUMIFS(#REF!,#REF!, $A3,#REF!, ">="&'Faturado mensal'!AE$2,#REF!, "<"&EOMONTH('Faturado mensal'!AE$2,0)) -> 0 | AF3: =SUMIFS(#REF!,#REF!, $A3,#REF!, ">="&'Faturado mensal'!AF$2,#REF!, "<"&EOMONTH('Faturado mensal'!AF$2,0)) -> 0 | AG3: =SUMIFS(#REF!,#REF!, $A3,#REF!, ">="&'Faturado mensal'!AG$2,#REF!, "<"&EOMONTH('Faturado mensal'!AG$2,0)) -> 0 | ... AK3: =SUMIFS(#REF!,#REF!, $A3,#REF!, ">="&'Faturado mensal'!AK$2,#REF!, "<"&EOMONTH('Faturado mensal'!AK$2,0)) -> 0 | AL3: =SUMIFS(#REF!,#REF!, $A3,#REF!, ">="&Z$2,#REF!, "<"&EOMONTH(AK$2,0)) -> 0
A4: CS0000649 | B4: 070006685 | C4: SERPRAM SERV PREST A M H LTDA | D4: Concluído | I4: SERPRAM SERV PREST A M H LTDA | J4: 30 DIAS | K4: SRSFAB | L4: PRGM . COMPRAS - SRS - FABRICA | M4: =SUMIFS(#REF!,#REF!, $A4,#REF!, ">="&'Faturado mensal'!M$2,#REF!, "<"&EOMONTH('Faturado mensal'!M$2,0)) -> 0 | N4: =SUMIFS(#REF!,#REF!, $A4,#REF!, ">="&'Faturado mensal'!N$2,#REF!, "<"&EOMONTH('Faturado mensal'!N$2,0)) -> 0 | O4: =SUMIFS(#REF!,#REF!, $A4,#REF!, ">="&'Faturado mensal'!O$2,#REF!, "<"&EOMONTH('Faturado mensal'!O$2,0)) -> 0 | P4: =SUMIFS(#REF!,#REF!, $A4,#REF!, ">="&'Faturado mensal'!P$2,#REF!, "<"&EOMONTH('Faturado mensal'!P$2,0)) -> 0 | Q4: =SUMIFS(#REF!,#REF!, $A4,#REF!, ">="&'Faturado mensal'!Q$2,#REF!, "<"&EOMONTH('Faturado mensal'!Q$2,0)) -> 0 | R4: =SUMIFS(#REF!,#REF!, $A4,#REF!, ">="&'Faturado mensal'!R$2,#REF!, "<"&EOMONTH('Faturado mensal'!R$2,0)) -> 0 | S4: =SUMIFS(#REF!,#REF!, $A4,#REF!, ">="&'Faturado mensal'!S$2,#REF!, "<"&EOMONTH('Faturado mensal'!S$2,0)) -> 0 | T4: =SUMIFS(#REF!,#REF!, $A4,#REF!, ">="&'Faturado mensal'!T$2,#REF!, "<"&EOMONTH('Faturado mensal'!T$2,0)) -> 0 | ... X4: =SUMIFS(#REF!,#REF!, $A4,#REF!, ">="&'Faturado mensal'!X$2,#REF!, "<"&EOMONTH('Faturado mensal'!X$2,0)) -> 0 | Y4: =SUMIFS(#REF!,#REF!, $A4,#REF!, ">="&'Faturado mensal'!M$2,#REF!, "<"&EOMONTH('Faturado mensal'!M$2,12)) -> 0 | Z4: =SUMIFS(#REF!,#REF!, $A4,#REF!, ">="&'Faturado mensal'!Z$2,#REF!, "<"&EOMONTH('Faturado mensal'!Z$2,0)) -> 0 | AA4: =SUMIFS(#REF!,#REF!, $A4,#REF!, ">="&'Faturado mensal'!AA$2,#REF!, "<"&EOMONTH('Faturado mensal'!AA$2,0)) -> 0 | AB4: =SUMIFS(#REF!,#REF!, $A4,#REF!, ">="&'Faturado mensal'!AB$2,#REF!, "<"&EOMONTH('Faturado mensal'!AB$2,0)) -> 0 | AC4: =SUMIFS(#REF!,#REF!, $A4,#REF!, ">="&'Faturado mensal'!AC$2,#REF!, "<"&EOMONTH('Faturado mensal'!AC$2,0)) -> 0 | AD4: =SUMIFS(#REF!,#REF!, $A4,#REF!, ">="&'Faturado mensal'!AD$2,#REF!, "<"&EOMONTH('Faturado mensal'!AD$2,0)) -> 0 | AE4: =SUMIFS(#REF!,#REF!, $A4,#REF!, ">="&'Faturado mensal'!AE$2,#REF!, "<"&EOMONTH('Faturado mensal'!AE$2,0)) -> 0 | AF4: =SUMIFS(#REF!,#REF!, $A4,#REF!, ">="&'Faturado mensal'!AF$2,#REF!, "<"&EOMONTH('Faturado mensal'!AF$2,0)) -> 0 | AG4: =SUMIFS(#REF!,#REF!, $A4,#REF!, ">="&'Faturado mensal'!AG$2,#REF!, "<"&EOMONTH('Faturado mensal'!AG$2,0)) -> 0 | ... AK4: =SUMIFS(#REF!,#REF!, $A4,#REF!, ">="&'Faturado mensal'!AK$2,#REF!, "<"&EOMONTH('Faturado mensal'!AK$2,0)) -> 0 | AL4: =SUMIFS(#REF!,#REF!, $A4,#REF!, ">="&Z$2,#REF!, "<"&EOMONTH(AK$2,0)) -> 0
A5: CS0000652 | B5: 070001769 | C5: METHODOS LABORATORIO, ANALISES CLIN | D5: Ativo | E5: RECURSOS HUMANOS | F5: SERVIÇOS PRESTADOS | G5: INDUSTRIAL SRS | H5: A | I5: METHODOS LABORATORIO, ANALISES | J5: 30 DIAS | K5: SRSADM | L5: COMPRAS - SRS - ADMINISTRAÇÃO | M5: =SUMIFS(#REF!,#REF!, $A5,#REF!, ">="&'Faturado mensal'!M$2,#REF!, "<"&EOMONTH('Faturado mensal'!M$2,0)) -> 0 | N5: =SUMIFS(#REF!,#REF!, $A5,#REF!, ">="&'Faturado mensal'!N$2,#REF!, "<"&EOMONTH('Faturado mensal'!N$2,0)) -> 241.23 | O5: =SUMIFS(#REF!,#REF!, $A5,#REF!, ">="&'Faturado mensal'!O$2,#REF!, "<"&EOMONTH('Faturado mensal'!O$2,0)) -> 122.56 | P5: =SUMIFS(#REF!,#REF!, $A5,#REF!, ">="&'Faturado mensal'!P$2,#REF!, "<"&EOMONTH('Faturado mensal'!P$2,0)) -> 0 | Q5: =SUMIFS(#REF!,#REF!, $A5,#REF!, ">="&'Faturado mensal'!Q$2,#REF!, "<"&EOMONTH('Faturado mensal'!Q$2,0)) -> 170.08 | R5: =SUMIFS(#REF!,#REF!, $A5,#REF!, ">="&'Faturado mensal'!R$2,#REF!, "<"&EOMONTH('Faturado mensal'!R$2,0)) -> 438.38 | S5: =SUMIFS(#REF!,#REF!, $A5,#REF!, ">="&'Faturado mensal'!S$2,#REF!, "<"&EOMONTH('Faturado mensal'!S$2,0)) -> 155.56 | T5: =SUMIFS(#REF!,#REF!, $A5,#REF!, ">="&'Faturado mensal'!T$2,#REF!, "<"&EOMONTH('Faturado mensal'!T$2,0)) -> 195.27 | ... X5: =SUMIFS(#REF!,#REF!, $A5,#REF!, ">="&'Faturado mensal'!X$2,#REF!, "<"&EOMONTH('Faturado mensal'!X$2,0)) -> 260.44 | Y5: =SUMIFS(#REF!,#REF!, $A5,#REF!, ">="&'Faturado mensal'!M$2,#REF!, "<"&EOMONTH('Faturado mensal'!M$2,12)) -> 2020.12 | Z5: =SUMIFS(#REF!,#REF!, $A5,#REF!, ">="&'Faturado mensal'!Z$2,#REF!, "<"&EOMONTH('Faturado mensal'!Z$2,0)) -> 0 | AA5: =SUMIFS(#REF!,#REF!, $A5,#REF!, ">="&'Faturado mensal'!AA$2,#REF!, "<"&EOMONTH('Faturado mensal'!AA$2,0)) -> 30.64 | AB5: =SUMIFS(#REF!,#REF!, $A5,#REF!, ">="&'Faturado mensal'!AB$2,#REF!, "<"&EOMONTH('Faturado mensal'!AB$2,0)) -> 0 | AC5: =SUMIFS(#REF!,#REF!, $A5,#REF!, ">="&'Faturado mensal'!AC$2,#REF!, "<"&EOMONTH('Faturado mensal'!AC$2,0)) -> 45.96 | AD5: =SUMIFS(#REF!,#REF!, $A5,#REF!, ">="&'Faturado mensal'!AD$2,#REF!, "<"&EOMONTH('Faturado mensal'!AD$2,0)) -> 173.86 | AE5: =SUMIFS(#REF!,#REF!, $A5,#REF!, ">="&'Faturado mensal'!AE$2,#REF!, "<"&EOMONTH('Faturado mensal'!AE$2,0)) -> 108.93 | AF5: =SUMIFS(#REF!,#REF!, $A5,#REF!, ">="&'Faturado mensal'!AF$2,#REF!, "<"&EOMONTH('Faturado mensal'!AF$2,0)) -> 0 | AG5: =SUMIFS(#REF!,#REF!, $A5,#REF!, ">="&'Faturado mensal'!AG$2,#REF!, "<"&EOMONTH('Faturado mensal'!AG$2,0)) -> 0 | ... AK5: =SUMIFS(#REF!,#REF!, $A5,#REF!, ">="&'Faturado mensal'!AK$2,#REF!, "<"&EOMONTH('Faturado mensal'!AK$2,0)) -> 0 | AL5: =SUMIFS(#REF!,#REF!, $A5,#REF!, ">="&Z$2,#REF!, "<"&EOMONTH(AK$2,0)) -> 359.39
A6: CS0000656 | B6: 090095495 | C6: SUL COM DE GAZ E ACESS LTDA ME | D6: Concluído | G6: INDUSTRIAL SRS | H6: B | I6: SUL COM DE GAZ E ACESS LTDA ME | J6: 30 DIAS | K6: SRSFAB | L6: PRGM . COMPRAS - SRS - FABRICA | M6: =SUMIFS(#REF!,#REF!, $A6,#REF!, ">="&'Faturado mensal'!M$2,#REF!, "<"&EOMONTH('Faturado mensal'!M$2,0)) -> 0 | N6: =SUMIFS(#REF!,#REF!, $A6,#REF!, ">="&'Faturado mensal'!N$2,#REF!, "<"&EOMONTH('Faturado mensal'!N$2,0)) -> 0 | O6: =SUMIFS(#REF!,#REF!, $A6,#REF!, ">="&'Faturado mensal'!O$2,#REF!, "<"&EOMONTH('Faturado mensal'!O$2,0)) -> 0 | P6: =SUMIFS(#REF!,#REF!, $A6,#REF!, ">="&'Faturado mensal'!P$2,#REF!, "<"&EOMONTH('Faturado mensal'!P$2,0)) -> 0 | Q6: =SUMIFS(#REF!,#REF!, $A6,#REF!, ">="&'Faturado mensal'!Q$2,#REF!, "<"&EOMONTH('Faturado mensal'!Q$2,0)) -> 0 | R6: =SUMIFS(#REF!,#REF!, $A6,#REF!, ">="&'Faturado mensal'!R$2,#REF!, "<"&EOMONTH('Faturado mensal'!R$2,0)) -> 0 | S6: =SUMIFS(#REF!,#REF!, $A6,#REF!, ">="&'Faturado mensal'!S$2,#REF!, "<"&EOMONTH('Faturado mensal'!S$2,0)) -> 0 | T6: =SUMIFS(#REF!,#REF!, $A6,#REF!, ">="&'Faturado mensal'!T$2,#REF!, "<"&EOMONTH('Faturado mensal'!T$2,0)) -> 0 | ... X6: =SUMIFS(#REF!,#REF!, $A6,#REF!, ">="&'Faturado mensal'!X$2,#REF!, "<"&EOMONTH('Faturado mensal'!X$2,0)) -> 0 | Y6: =SUMIFS(#REF!,#REF!, $A6,#REF!, ">="&'Faturado mensal'!M$2,#REF!, "<"&EOMONTH('Faturado mensal'!M$2,12)) -> 0 | Z6: =SUMIFS(#REF!,#REF!, $A6,#REF!, ">="&'Faturado mensal'!Z$2,#REF!, "<"&EOMONTH('Faturado mensal'!Z$2,0)) -> 0 | AA6: =SUMIFS(#REF!,#REF!, $A6,#REF!, ">="&'Faturado mensal'!AA$2,#REF!, "<"&EOMONTH('Faturado mensal'!AA$2,0)) -> 0 | AB6: =SUMIFS(#REF!,#REF!, $A6,#REF!, ">="&'Faturado mensal'!AB$2,#REF!, "<"&EOMONTH('Faturado mensal'!AB$2,0)) -> 0 | AC6: =SUMIFS(#REF!,#REF!, $A6,#REF!, ">="&'Faturado mensal'!AC$2,#REF!, "<"&EOMONTH('Faturado mensal'!AC$2,0)) -> 0 | AD6: =SUMIFS(#REF!,#REF!, $A6,#REF!, ">="&'Faturado mensal'!AD$2,#REF!, "<"&EOMONTH('Faturado mensal'!AD$2,0)) -> 0 | AE6: =SUMIFS(#REF!,#REF!, $A6,#REF!, ">="&'Faturado mensal'!AE$2,#REF!, "<"&EOMONTH('Faturado mensal'!AE$2,0)) -> 0 | AF6: =SUMIFS(#REF!,#REF!, $A6,#REF!, ">="&'Faturado mensal'!AF$2,#REF!, "<"&EOMONTH('Faturado mensal'!AF$2,0)) -> 0 | AG6: =SUMIFS(#REF!,#REF!, $A6,#REF!, ">="&'Faturado mensal'!AG$2,#REF!, "<"&EOMONTH('Faturado mensal'!AG$2,0)) -> 0 | ... AK6: =SUMIFS(#REF!,#REF!, $A6,#REF!, ">="&'Faturado mensal'!AK$2,#REF!, "<"&EOMONTH('Faturado mensal'!AK$2,0)) -> 0 | AL6: =SUMIFS(#REF!,#REF!, $A6,#REF!, ">="&Z$2,#REF!, "<"&EOMONTH(AK$2,0)) -> 0
A7: CS0000662 | B7: 090000133 | C7: EXTELLPP EQUIP.E EXTINT.LTDA | D7: Ativo | E7: QSMA | F7: SERVIÇOS PRESTADOS | G7: INDUSTRIAL VIES | H7: C | I7: EXTELLPP EQUIP.E EXTINT.LTDA | J7: 15 DIAS | K7: VIESFB | L7: PRGM .COMPRAS - VIES - FABRICA | M7: =SUMIFS(#REF!,#REF!, $A7,#REF!, ">="&'Faturado mensal'!M$2,#REF!, "<"&EOMONTH('Faturado mensal'!M$2,0)) -> 1000 | N7: =SUMIFS(#REF!,#REF!, $A7,#REF!, ">="&'Faturado mensal'!N$2,#REF!, "<"&EOMONTH('Faturado mensal'!N$2,0)) -> 1000 | O7: =SUMIFS(#REF!,#REF!, $A7,#REF!, ">="&'Faturado mensal'!O$2,#REF!, "<"&EOMONTH('Faturado mensal'!O$2,0)) -> 1000 | P7: =SUMIFS(#REF!,#REF!, $A7,#REF!, ">="&'Faturado mensal'!P$2,#REF!, "<"&EOMONTH('Faturado mensal'!P$2,0)) -> 1000 | Q7: =SUMIFS(#REF!,#REF!, $A7,#REF!, ">="&'Faturado mensal'!Q$2,#REF!, "<"&EOMONTH('Faturado mensal'!Q$2,0)) -> 1000 | R7: =SUMIFS(#REF!,#REF!, $A7,#REF!, ">="&'Faturado mensal'!R$2,#REF!, "<"&EOMONTH('Faturado mensal'!R$2,0)) -> 1000 | S7: =SUMIFS(#REF!,#REF!, $A7,#REF!, ">="&'Faturado mensal'!S$2,#REF!, "<"&EOMONTH('Faturado mensal'!S$2,0)) -> 1000 | T7: =SUMIFS(#REF!,#REF!, $A7,#REF!, ">="&'Faturado mensal'!T$2,#REF!, "<"&EOMONTH('Faturado mensal'!T$2,0)) -> 0 | ... X7: =SUMIFS(#REF!,#REF!, $A7,#REF!, ">="&'Faturado mensal'!X$2,#REF!, "<"&EOMONTH('Faturado mensal'!X$2,0)) -> 1000 | Y7: =SUMIFS(#REF!,#REF!, $A7,#REF!, ">="&'Faturado mensal'!M$2,#REF!, "<"&EOMONTH('Faturado mensal'!M$2,12)) -> 13000 | Z7: =SUMIFS(#REF!,#REF!, $A7,#REF!, ">="&'Faturado mensal'!Z$2,#REF!, "<"&EOMONTH('Faturado mensal'!Z$2,0)) -> 1000 | AA7: =SUMIFS(#REF!,#REF!, $A7,#REF!, ">="&'Faturado mensal'!AA$2,#REF!, "<"&EOMONTH('Faturado mensal'!AA$2,0)) -> 1000 | AB7: =SUMIFS(#REF!,#REF!, $A7,#REF!, ">="&'Faturado mensal'!AB$2,#REF!, "<"&EOMONTH('Faturado mensal'!AB$2,0)) -> 1000 | AC7: =SUMIFS(#REF!,#REF!, $A7,#REF!, ">="&'Faturado mensal'!AC$2,#REF!, "<"&EOMONTH('Faturado mensal'!AC$2,0)) -> 1000 | AD7: =SUMIFS(#REF!,#REF!, $A7,#REF!, ">="&'Faturado mensal'!AD$2,#REF!, "<"&EOMONTH('Faturado mensal'!AD$2,0)) -> 0 | AE7: =SUMIFS(#REF!,#REF!, $A7,#REF!, ">="&'Faturado mensal'!AE$2,#REF!, "<"&EOMONTH('Faturado mensal'!AE$2,0)) -> 2000 | AF7: =SUMIFS(#REF!,#REF!, $A7,#REF!, ">="&'Faturado mensal'!AF$2,#REF!, "<"&EOMONTH('Faturado mensal'!AF$2,0)) -> 0 | AG7: =SUMIFS(#REF!,#REF!, $A7,#REF!, ">="&'Faturado mensal'!AG$2,#REF!, "<"&EOMONTH('Faturado mensal'!AG$2,0)) -> 0 | ... AK7: =SUMIFS(#REF!,#REF!, $A7,#REF!, ">="&'Faturado mensal'!AK$2,#REF!, "<"&EOMONTH('Faturado mensal'!AK$2,0)) -> 0 | AL7: =SUMIFS(#REF!,#REF!, $A7,#REF!, ">="&Z$2,#REF!, "<"&EOMONTH(AK$2,0)) -> 6000
A8: CS0000663 | B8: 090005248 | C8: FORCA DELTA INT.CON.ASS.S.LTDA | D8: Concluído | I8: FORCA DELTA INT.CON.ASS.S.LTDA | J8: 30 DIAS | K8: VIESFB | L8: PRGM .COMPRAS - VIES - FABRICA | M8: =SUMIFS(#REF!,#REF!, $A8,#REF!, ">="&'Faturado mensal'!M$2,#REF!, "<"&EOMONTH('Faturado mensal'!M$2,0)) -> 0 | N8: =SUMIFS(#REF!,#REF!, $A8,#REF!, ">="&'Faturado mensal'!N$2,#REF!, "<"&EOMONTH('Faturado mensal'!N$2,0)) -> 0 | O8: =SUMIFS(#REF!,#REF!, $A8,#REF!, ">="&'Faturado mensal'!O$2,#REF!, "<"&EOMONTH('Faturado mensal'!O$2,0)) -> 0 | P8: =SUMIFS(#REF!,#REF!, $A8,#REF!, ">="&'Faturado mensal'!P$2,#REF!, "<"&EOMONTH('Faturado mensal'!P$2,0)) -> 0 | Q8: =SUMIFS(#REF!,#REF!, $A8,#REF!, ">="&'Faturado mensal'!Q$2,#REF!, "<"&EOMONTH('Faturado mensal'!Q$2,0)) -> 0 | R8: =SUMIFS(#REF!,#REF!, $A8,#REF!, ">="&'Faturado mensal'!R$2,#REF!, "<"&EOMONTH('Faturado mensal'!R$2,0)) -> 0 | S8: =SUMIFS(#REF!,#REF!, $A8,#REF!, ">="&'Faturado mensal'!S$2,#REF!, "<"&EOMONTH('Faturado mensal'!S$2,0)) -> 0 | T8: =SUMIFS(#REF!,#REF!, $A8,#REF!, ">="&'Faturado mensal'!T$2,#REF!, "<"&EOMONTH('Faturado mensal'!T$2,0)) -> 0 | ... X8: =SUMIFS(#REF!,#REF!, $A8,#REF!, ">="&'Faturado mensal'!X$2,#REF!, "<"&EOMONTH('Faturado mensal'!X$2,0)) -> 0 | Y8: =SUMIFS(#REF!,#REF!, $A8,#REF!, ">="&'Faturado mensal'!M$2,#REF!, "<"&EOMONTH('Faturado mensal'!M$2,12)) -> 0 | Z8: =SUMIFS(#REF!,#REF!, $A8,#REF!, ">="&'Faturado mensal'!Z$2,#REF!, "<"&EOMONTH('Faturado mensal'!Z$2,0)) -> 0 | AA8: =SUMIFS(#REF!,#REF!, $A8,#REF!, ">="&'Faturado mensal'!AA$2,#REF!, "<"&EOMONTH('Faturado mensal'!AA$2,0)) -> 0 | AB8: =SUMIFS(#REF!,#REF!, $A8,#REF!, ">="&'Faturado mensal'!AB$2,#REF!, "<"&EOMONTH('Faturado mensal'!AB$2,0)) -> 0 | AC8: =SUMIFS(#REF!,#REF!, $A8,#REF!, ">="&'Faturado mensal'!AC$2,#REF!, "<"&EOMONTH('Faturado mensal'!AC$2,0)) -> 0 | AD8: =SUMIFS(#REF!,#REF!, $A8,#REF!, ">="&'Faturado mensal'!AD$2,#REF!, "<"&EOMONTH('Faturado mensal'!AD$2,0)) -> 0 | AE8: =SUMIFS(#REF!,#REF!, $A8,#REF!, ">="&'Faturado mensal'!AE$2,#REF!, "<"&EOMONTH('Faturado mensal'!AE$2,0)) -> 0 | AF8: =SUMIFS(#REF!,#REF!, $A8,#REF!, ">="&'Faturado mensal'!AF$2,#REF!, "<"&EOMONTH('Faturado mensal'!AF$2,0)) -> 0 | AG8: =SUMIFS(#REF!,#REF!, $A8,#REF!, ">="&'Faturado mensal'!AG$2,#REF!, "<"&EOMONTH('Faturado mensal'!AG$2,0)) -> 0 | ... AK8: =SUMIFS(#REF!,#REF!, $A8,#REF!, ">="&'Faturado mensal'!AK$2,#REF!, "<"&EOMONTH('Faturado mensal'!AK$2,0)) -> 0 | AL8: =SUMIFS(#REF!,#REF!, $A8,#REF!, ">="&Z$2,#REF!, "<"&EOMONTH(AK$2,0)) -> 0
A9: CS0000666 | B9: 070075619 | C9: KOLETUS TRANS COLE RESID LTDA | D9: Ativo | E9: QSMA | F9: SERVIÇOS PRESTADOS | G9: INDUSTRIAL VIES | H9: A | I9: KOLETUS TRANS COLE RESID LTDA | J9: 30 DIAS | K9: VIESFB | L9: PRGM .COMPRAS - VIES - FABRICA | M9: =SUMIFS(#REF!,#REF!, $A9,#REF!, ">="&'Faturado mensal'!M$2,#REF!, "<"&EOMONTH('Faturado mensal'!M$2,0)) -> 28530.44 | N9: =SUMIFS(#REF!,#REF!, $A9,#REF!, ">="&'Faturado mensal'!N$2,#REF!, "<"&EOMONTH('Faturado mensal'!N$2,0)) -> 0 | O9: =SUMIFS(#REF!,#REF!, $A9,#REF!, ">="&'Faturado mensal'!O$2,#REF!, "<"&EOMONTH('Faturado mensal'!O$2,0)) -> 50133.85 | P9: =SUMIFS(#REF!,#REF!, $A9,#REF!, ">="&'Faturado mensal'!P$2,#REF!, "<"&EOMONTH('Faturado mensal'!P$2,0)) -> 0 | Q9: =SUMIFS(#REF!,#REF!, $A9,#REF!, ">="&'Faturado mensal'!Q$2,#REF!, "<"&EOMONTH('Faturado mensal'!Q$2,0)) -> 50998.86 | R9: =SUMIFS(#REF!,#REF!, $A9,#REF!, ">="&'Faturado mensal'!R$2,#REF!, "<"&EOMONTH('Faturado mensal'!R$2,0)) -> 0 | S9: =SUMIFS(#REF!,#REF!, $A9,#REF!, ">="&'Faturado mensal'!S$2,#REF!, "<"&EOMONTH('Faturado mensal'!S$2,0)) -> 28535.23 | T9: =SUMIFS(#REF!,#REF!, $A9,#REF!, ">="&'Faturado mensal'!T$2,#REF!, "<"&EOMONTH('Faturado mensal'!T$2,0)) -> 54722.23 | ... X9: =SUMIFS(#REF!,#REF!, $A9,#REF!, ">="&'Faturado mensal'!X$2,#REF!, "<"&EOMONTH('Faturado mensal'!X$2,0)) -> 49878.03 | Y9: =SUMIFS(#REF!,#REF!, $A9,#REF!, ">="&'Faturado mensal'!M$2,#REF!, "<"&EOMONTH('Faturado mensal'!M$2,12)) -> 332211.3 | Z9: =SUMIFS(#REF!,#REF!, $A9,#REF!, ">="&'Faturado mensal'!Z$2,#REF!, "<"&EOMONTH('Faturado mensal'!Z$2,0)) -> 17467.9 | AA9: =SUMIFS(#REF!,#REF!, $A9,#REF!, ">="&'Faturado mensal'!AA$2,#REF!, "<"&EOMONTH('Faturado mensal'!AA$2,0)) -> 20128.94 | AB9: =SUMIFS(#REF!,#REF!, $A9,#REF!, ">="&'Faturado mensal'!AB$2,#REF!, "<"&EOMONTH('Faturado mensal'!AB$2,0)) -> 15777.94 | AC9: =SUMIFS(#REF!,#REF!, $A9,#REF!, ">="&'Faturado mensal'!AC$2,#REF!, "<"&EOMONTH('Faturado mensal'!AC$2,0)) -> 17028.24 | AD9: =SUMIFS(#REF!,#REF!, $A9,#REF!, ">="&'Faturado mensal'!AD$2,#REF!, "<"&EOMONTH('Faturado mensal'!AD$2,0)) -> 16481.86 | AE9: =SUMIFS(#REF!,#REF!, $A9,#REF!, ">="&'Faturado mensal'!AE$2,#REF!, "<"&EOMONTH('Faturado mensal'!AE$2,0)) -> 0 | AF9: =SUMIFS(#REF!,#REF!, $A9,#REF!, ">="&'Faturado mensal'!AF$2,#REF!, "<"&EOMONTH('Faturado mensal'!AF$2,0)) -> 0 | AG9: =SUMIFS(#REF!,#REF!, $A9,#REF!, ">="&'Faturado mensal'!AG$2,#REF!, "<"&EOMONTH('Faturado mensal'!AG$2,0)) -> 0 | ... AK9: =SUMIFS(#REF!,#REF!, $A9,#REF!, ">="&'Faturado mensal'!AK$2,#REF!, "<"&EOMONTH('Faturado mensal'!AK$2,0)) -> 0 | AL9: =SUMIFS(#REF!,#REF!, $A9,#REF!, ">="&Z$2,#REF!, "<"&EOMONTH(AK$2,0)) -> 86884.88
A10: CS0000667 | B10: 070001498 | C10: RENAN V. B. SILVA CONSULTORIA E SER | D10: Ativo | E10: MANUFATURA VIES | F10: TERCEIROS | G10: INDUSTRIAL VIES | H10: C | I10: RENAN V. B. SILVA CONSULTORIA | J10: 30 DIAS | K10: VIESFB | L10: PRGM .COMPRAS - VIES - FABRICA | M10: =SUMIFS(#REF!,#REF!, $A10,#REF!, ">="&'Faturado mensal'!M$2,#REF!, "<"&EOMONTH('Faturado mensal'!M$2,0)) -> 22365 | N10: =SUMIFS(#REF!,#REF!, $A10,#REF!, ">="&'Faturado mensal'!N$2,#REF!, "<"&EOMONTH('Faturado mensal'!N$2,0)) -> 0 | O10: =SUMIFS(#REF!,#REF!, $A10,#REF!, ">="&'Faturado mensal'!O$2,#REF!, "<"&EOMONTH('Faturado mensal'!O$2,0)) -> 3420 | P10: =SUMIFS(#REF!,#REF!, $A10,#REF!, ">="&'Faturado mensal'!P$2,#REF!, "<"&EOMONTH('Faturado mensal'!P$2,0)) -> 0 | Q10: =SUMIFS(#REF!,#REF!, $A10,#REF!, ">="&'Faturado mensal'!Q$2,#REF!, "<"&EOMONTH('Faturado mensal'!Q$2,0)) -> 5200 | R10: =SUMIFS(#REF!,#REF!, $A10,#REF!, ">="&'Faturado mensal'!R$2,#REF!, "<"&EOMONTH('Faturado mensal'!R$2,0)) -> 0 | S10: =SUMIFS(#REF!,#REF!, $A10,#REF!, ">="&'Faturado mensal'!S$2,#REF!, "<"&EOMONTH('Faturado mensal'!S$2,0)) -> 0 | T10: =SUMIFS(#REF!,#REF!, $A10,#REF!, ">="&'Faturado mensal'!T$2,#REF!, "<"&EOMONTH('Faturado mensal'!T$2,0)) -> 5400 | ... X10: =SUMIFS(#REF!,#REF!, $A10,#REF!, ">="&'Faturado mensal'!X$2,#REF!, "<"&EOMONTH('Faturado mensal'!X$2,0)) -> 0 | Y10: =SUMIFS(#REF!,#REF!, $A10,#REF!, ">="&'Faturado mensal'!M$2,#REF!, "<"&EOMONTH('Faturado mensal'!M$2,12)) -> 36385 | Z10: =SUMIFS(#REF!,#REF!, $A10,#REF!, ">="&'Faturado mensal'!Z$2,#REF!, "<"&EOMONTH('Faturado mensal'!Z$2,0)) -> 0 | AA10: =SUMIFS(#REF!,#REF!, $A10,#REF!, ">="&'Faturado mensal'!AA$2,#REF!, "<"&EOMONTH('Faturado mensal'!AA$2,0)) -> 0 | AB10: =SUMIFS(#REF!,#REF!, $A10,#REF!, ">="&'Faturado mensal'!AB$2,#REF!, "<"&EOMONTH('Faturado mensal'!AB$2,0)) -> 800 | AC10: =SUMIFS(#REF!,#REF!, $A10,#REF!, ">="&'Faturado mensal'!AC$2,#REF!, "<"&EOMONTH('Faturado mensal'!AC$2,0)) -> 0 | AD10: =SUMIFS(#REF!,#REF!, $A10,#REF!, ">="&'Faturado mensal'!AD$2,#REF!, "<"&EOMONTH('Faturado mensal'!AD$2,0)) -> 0 | AE10: =SUMIFS(#REF!,#REF!, $A10,#REF!, ">="&'Faturado mensal'!AE$2,#REF!, "<"&EOMONTH('Faturado mensal'!AE$2,0)) -> 0 | AF10: =SUMIFS(#REF!,#REF!, $A10,#REF!, ">="&'Faturado mensal'!AF$2,#REF!, "<"&EOMONTH('Faturado mensal'!AF$2,0)) -> 0 | AG10: =SUMIFS(#REF!,#REF!, $A10,#REF!, ">="&'Faturado mensal'!AG$2,#REF!, "<"&EOMONTH('Faturado mensal'!AG$2,0)) -> 0 | ... AK10: =SUMIFS(#REF!,#REF!, $A10,#REF!, ">="&'Faturado mensal'!AK$2,#REF!, "<"&EOMONTH('Faturado mensal'!AK$2,0)) -> 0 | AL10: =SUMIFS(#REF!,#REF!, $A10,#REF!, ">="&Z$2,#REF!, "<"&EOMONTH(AK$2,0)) -> 800
A11: CS0000669 | B11: 090095563 | C11: AEJ PAULISTA SERVICOS LTDA ME | D11: Concluído | I11: AEJ PAULISTA SERVICOS LTDA ME | J11: 30 DIAS | K11: VIESFB | L11: PRGM .COMPRAS - VIES - FABRICA | M11: =SUMIFS(#REF!,#REF!, $A11,#REF!, ">="&'Faturado mensal'!M$2,#REF!, "<"&EOMONTH('Faturado mensal'!M$2,0)) -> 0 | N11: =SUMIFS(#REF!,#REF!, $A11,#REF!, ">="&'Faturado mensal'!N$2,#REF!, "<"&EOMONTH('Faturado mensal'!N$2,0)) -> 0 | O11: =SUMIFS(#REF!,#REF!, $A11,#REF!, ">="&'Faturado mensal'!O$2,#REF!, "<"&EOMONTH('Faturado mensal'!O$2,0)) -> 0 | P11: =SUMIFS(#REF!,#REF!, $A11,#REF!, ">="&'Faturado mensal'!P$2,#REF!, "<"&EOMONTH('Faturado mensal'!P$2,0)) -> 0 | Q11: =SUMIFS(#REF!,#REF!, $A11,#REF!, ">="&'Faturado mensal'!Q$2,#REF!, "<"&EOMONTH('Faturado mensal'!Q$2,0)) -> 0 | R11: =SUMIFS(#REF!,#REF!, $A11,#REF!, ">="&'Faturado mensal'!R$2,#REF!, "<"&EOMONTH('Faturado mensal'!R$2,0)) -> 0 | S11: =SUMIFS(#REF!,#REF!, $A11,#REF!, ">="&'Faturado mensal'!S$2,#REF!, "<"&EOMONTH('Faturado mensal'!S$2,0)) -> 0 | T11: =SUMIFS(#REF!,#REF!, $A11,#REF!, ">="&'Faturado mensal'!T$2,#REF!, "<"&EOMONTH('Faturado mensal'!T$2,0)) -> 0 | ... X11: =SUMIFS(#REF!,#REF!, $A11,#REF!, ">="&'Faturado mensal'!X$2,#REF!, "<"&EOMONTH('Faturado mensal'!X$2,0)) -> 0 | Y11: =SUMIFS(#REF!,#REF!, $A11,#REF!, ">="&'Faturado mensal'!M$2,#REF!, "<"&EOMONTH('Faturado mensal'!M$2,12)) -> 0 | Z11: =SUMIFS(#REF!,#REF!, $A11,#REF!, ">="&'Faturado mensal'!Z$2,#REF!, "<"&EOMONTH('Faturado mensal'!Z$2,0)) -> 0 | AA11: =SUMIFS(#REF!,#REF!, $A11,#REF!, ">="&'Faturado mensal'!AA$2,#REF!, "<"&EOMONTH('Faturado mensal'!AA$2,0)) -> 0 | AB11: =SUMIFS(#REF!,#REF!, $A11,#REF!, ">="&'Faturado mensal'!AB$2,#REF!, "<"&EOMONTH('Faturado mensal'!AB$2,0)) -> 0 | AC11: =SUMIFS(#REF!,#REF!, $A11,#REF!, ">="&'Faturado mensal'!AC$2,#REF!, "<"&EOMONTH('Faturado mensal'!AC$2,0)) -> 0 | AD11: =SUMIFS(#REF!,#REF!, $A11,#REF!, ">="&'Faturado mensal'!AD$2,#REF!, "<"&EOMONTH('Faturado mensal'!AD$2,0)) -> 0 | AE11: =SUMIFS(#REF!,#REF!, $A11,#REF!, ">="&'Faturado mensal'!AE$2,#REF!, "<"&EOMONTH('Faturado mensal'!AE$2,0)) -> 0 | AF11: =SUMIFS(#REF!,#REF!, $A11,#REF!, ">="&'Faturado mensal'!AF$2,#REF!, "<"&EOMONTH('Faturado mensal'!AF$2,0)) -> 0 | AG11: =SUMIFS(#REF!,#REF!, $A11,#REF!, ">="&'Faturado mensal'!AG$2,#REF!, "<"&EOMONTH('Faturado mensal'!AG$2,0)) -> 0 | ... AK11: =SUMIFS(#REF!,#REF!, $A11,#REF!, ">="&'Faturado mensal'!AK$2,#REF!, "<"&EOMONTH('Faturado mensal'!AK$2,0)) -> 0 | AL11: =SUMIFS(#REF!,#REF!, $A11,#REF!, ">="&Z$2,#REF!, "<"&EOMONTH(AK$2,0)) -> 0
A12: CS0000676 | B12: 070065548 | C12: TUV SUD SFDK LABORATORIO DE ANALISE | D12: Ativo | E12: QSMA | F12: SERVIÇOS PRESTADOS | G12: INDUSTRIAL SRS | H12: B | I12: TUV SUD SFDK LABORATORIO DE AN | J12: 30 DIAS | K12: SRSFAB | L12: PRGM . COMPRAS - SRS - FABRICA | M12: =SUMIFS(#REF!,#REF!, $A12,#REF!, ">="&'Faturado mensal'!M$2,#REF!, "<"&EOMONTH('Faturado mensal'!M$2,0)) -> 0 | N12: =SUMIFS(#REF!,#REF!, $A12,#REF!, ">="&'Faturado mensal'!N$2,#REF!, "<"&EOMONTH('Faturado mensal'!N$2,0)) -> 0 | O12: =SUMIFS(#REF!,#REF!, $A12,#REF!, ">="&'Faturado mensal'!O$2,#REF!, "<"&EOMONTH('Faturado mensal'!O$2,0)) -> 0 | P12: =SUMIFS(#REF!,#REF!, $A12,#REF!, ">="&'Faturado mensal'!P$2,#REF!, "<"&EOMONTH('Faturado mensal'!P$2,0)) -> 0 | Q12: =SUMIFS(#REF!,#REF!, $A12,#REF!, ">="&'Faturado mensal'!Q$2,#REF!, "<"&EOMONTH('Faturado mensal'!Q$2,0)) -> 0 | R12: =SUMIFS(#REF!,#REF!, $A12,#REF!, ">="&'Faturado mensal'!R$2,#REF!, "<"&EOMONTH('Faturado mensal'!R$2,0)) -> 0 | S12: =SUMIFS(#REF!,#REF!, $A12,#REF!, ">="&'Faturado mensal'!S$2,#REF!, "<"&EOMONTH('Faturado mensal'!S$2,0)) -> 0 | T12: =SUMIFS(#REF!,#REF!, $A12,#REF!, ">="&'Faturado mensal'!T$2,#REF!, "<"&EOMONTH('Faturado mensal'!T$2,0)) -> 0 | ... X12: =SUMIFS(#REF!,#REF!, $A12,#REF!, ">="&'Faturado mensal'!X$2,#REF!, "<"&EOMONTH('Faturado mensal'!X$2,0)) -> 0 | Y12: =SUMIFS(#REF!,#REF!, $A12,#REF!, ">="&'Faturado mensal'!M$2,#REF!, "<"&EOMONTH('Faturado mensal'!M$2,12)) -> 20128.7 | Z12: =SUMIFS(#REF!,#REF!, $A12,#REF!, ">="&'Faturado mensal'!Z$2,#REF!, "<"&EOMONTH('Faturado mensal'!Z$2,0)) -> 1250.01 | AA12: =SUMIFS(#REF!,#REF!, $A12,#REF!, ">="&'Faturado mensal'!AA$2,#REF!, "<"&EOMONTH('Faturado mensal'!AA$2,0)) -> 0 | AB12: =SUMIFS(#REF!,#REF!, $A12,#REF!, ">="&'Faturado mensal'!AB$2,#REF!, "<"&EOMONTH('Faturado mensal'!AB$2,0)) -> 0 | AC12: =SUMIFS(#REF!,#REF!, $A12,#REF!, ">="&'Faturado mensal'!AC$2,#REF!, "<"&EOMONTH('Faturado mensal'!AC$2,0)) -> 0 | AD12: =SUMIFS(#REF!,#REF!, $A12,#REF!, ">="&'Faturado mensal'!AD$2,#REF!, "<"&EOMONTH('Faturado mensal'!AD$2,0)) -> 0 | AE12: =SUMIFS(#REF!,#REF!, $A12,#REF!, ">="&'Faturado mensal'!AE$2,#REF!, "<"&EOMONTH('Faturado mensal'!AE$2,0)) -> 0 | AF12: =SUMIFS(#REF!,#REF!, $A12,#REF!, ">="&'Faturado mensal'!AF$2,#REF!, "<"&EOMONTH('Faturado mensal'!AF$2,0)) -> 0 | AG12: =SUMIFS(#REF!,#REF!, $A12,#REF!, ">="&'Faturado mensal'!AG$2,#REF!, "<"&EOMONTH('Faturado mensal'!AG$2,0)) -> 0 | ... AK12: =SUMIFS(#REF!,#REF!, $A12,#REF!, ">="&'Faturado mensal'!AK$2,#REF!, "<"&EOMONTH('Faturado mensal'!AK$2,0)) -> 0 | AL12: =SUMIFS(#REF!,#REF!, $A12,#REF!, ">="&Z$2,#REF!, "<"&EOMONTH(AK$2,0)) -> 1250.01
A13: CS0000677 | B13: 070001699 | C13: WELLIMAR GONCALVES DE MEIRA 7296884 | D13: Concluído | I13: WELLIMAR GONCALVES DE MEIRA 72 | J13: 30 DIAS | K13: SRSFAB | L13: PRGM . COMPRAS - SRS - FABRICA | M13: =SUMIFS(#REF!,#REF!, $A13,#REF!, ">="&'Faturado mensal'!M$2,#REF!, "<"&EOMONTH('Faturado mensal'!M$2,0)) -> 0 | N13: =SUMIFS(#REF!,#REF!, $A13,#REF!, ">="&'Faturado mensal'!N$2,#REF!, "<"&EOMONTH('Faturado mensal'!N$2,0)) -> 0 | O13: =SUMIFS(#REF!,#REF!, $A13,#REF!, ">="&'Faturado mensal'!O$2,#REF!, "<"&EOMONTH('Faturado mensal'!O$2,0)) -> 0 | P13: =SUMIFS(#REF!,#REF!, $A13,#REF!, ">="&'Faturado mensal'!P$2,#REF!, "<"&EOMONTH('Faturado mensal'!P$2,0)) -> 0 | Q13: =SUMIFS(#REF!,#REF!, $A13,#REF!, ">="&'Faturado mensal'!Q$2,#REF!, "<"&EOMONTH('Faturado mensal'!Q$2,0)) -> 0 | R13: =SUMIFS(#REF!,#REF!, $A13,#REF!, ">="&'Faturado mensal'!R$2,#REF!, "<"&EOMONTH('Faturado mensal'!R$2,0)) -> 0 | S13: =SUMIFS(#REF!,#REF!, $A13,#REF!, ">="&'Faturado mensal'!S$2,#REF!, "<"&EOMONTH('Faturado mensal'!S$2,0)) -> 0 | T13: =SUMIFS(#REF!,#REF!, $A13,#REF!, ">="&'Faturado mensal'!T$2,#REF!, "<"&EOMONTH('Faturado mensal'!T$2,0)) -> 0 | ... X13: =SUMIFS(#REF!,#REF!, $A13,#REF!, ">="&'Faturado mensal'!X$2,#REF!, "<"&EOMONTH('Faturado mensal'!X$2,0)) -> 0 | Y13: =SUMIFS(#REF!,#REF!, $A13,#REF!, ">="&'Faturado mensal'!M$2,#REF!, "<"&EOMONTH('Faturado mensal'!M$2,12)) -> 0 | Z13: =SUMIFS(#REF!,#REF!, $A13,#REF!, ">="&'Faturado mensal'!Z$2,#REF!, "<"&EOMONTH('Faturado mensal'!Z$2,0)) -> 0 | AA13: =SUMIFS(#REF!,#REF!, $A13,#REF!, ">="&'Faturado mensal'!AA$2,#REF!, "<"&EOMONTH('Faturado mensal'!AA$2,0)) -> 0 | AB13: =SUMIFS(#REF!,#REF!, $A13,#REF!, ">="&'Faturado mensal'!AB$2,#REF!, "<"&EOMONTH('Faturado mensal'!AB$2,0)) -> 0 | AC13: =SUMIFS(#REF!,#REF!, $A13,#REF!, ">="&'Faturado mensal'!AC$2,#REF!, "<"&EOMONTH('Faturado mensal'!AC$2,0)) -> 0 | AD13: =SUMIFS(#REF!,#REF!, $A13,#REF!, ">="&'Faturado mensal'!AD$2,#REF!, "<"&EOMONTH('Faturado mensal'!AD$2,0)) -> 0 | AE13: =SUMIFS(#REF!,#REF!, $A13,#REF!, ">="&'Faturado mensal'!AE$2,#REF!, "<"&EOMONTH('Faturado mensal'!AE$2,0)) -> 0 | AF13: =SUMIFS(#REF!,#REF!, $A13,#REF!, ">="&'Faturado mensal'!AF$2,#REF!, "<"&EOMONTH('Faturado mensal'!AF$2,0)) -> 0 | AG13: =SUMIFS(#REF!,#REF!, $A13,#REF!, ">="&'Faturado mensal'!AG$2,#REF!, "<"&EOMONTH('Faturado mensal'!AG$2,0)) -> 0 | ... AK13: =SUMIFS(#REF!,#REF!, $A13,#REF!, ">="&'Faturado mensal'!AK$2,#REF!, "<"&EOMONTH('Faturado mensal'!AK$2,0)) -> 0 | AL13: =SUMIFS(#REF!,#REF!, $A13,#REF!, ">="&Z$2,#REF!, "<"&EOMONTH(AK$2,0)) -> 0
A14: CS0000678 | B14: 070001703 | C14: SERI.E DESIGN LTDA. | D14: Concluído | G14: INDUSTRIAL SRS | H14: B | I14: SERI.E DESIGN LTDA. | J14: 30 DIAS | K14: SRSFAB | L14: PRGM . COMPRAS - SRS - FABRICA | M14: =SUMIFS(#REF!,#REF!, $A14,#REF!, ">="&'Faturado mensal'!M$2,#REF!, "<"&EOMONTH('Faturado mensal'!M$2,0)) -> 0 | N14: =SUMIFS(#REF!,#REF!, $A14,#REF!, ">="&'Faturado mensal'!N$2,#REF!, "<"&EOMONTH('Faturado mensal'!N$2,0)) -> 0 | O14: =SUMIFS(#REF!,#REF!, $A14,#REF!, ">="&'Faturado mensal'!O$2,#REF!, "<"&EOMONTH('Faturado mensal'!O$2,0)) -> 0 | P14: =SUMIFS(#REF!,#REF!, $A14,#REF!, ">="&'Faturado mensal'!P$2,#REF!, "<"&EOMONTH('Faturado mensal'!P$2,0)) -> 0 | Q14: =SUMIFS(#REF!,#REF!, $A14,#REF!, ">="&'Faturado mensal'!Q$2,#REF!, "<"&EOMONTH('Faturado mensal'!Q$2,0)) -> 0 | R14: =SUMIFS(#REF!,#REF!, $A14,#REF!, ">="&'Faturado mensal'!R$2,#REF!, "<"&EOMONTH('Faturado mensal'!R$2,0)) -> 0 | S14: =SUMIFS(#REF!,#REF!, $A14,#REF!, ">="&'Faturado mensal'!S$2,#REF!, "<"&EOMONTH('Faturado mensal'!S$2,0)) -> 0 | T14: =SUMIFS(#REF!,#REF!, $A14,#REF!, ">="&'Faturado mensal'!T$2,#REF!, "<"&EOMONTH('Faturado mensal'!T$2,0)) -> 0 | ... X14: =SUMIFS(#REF!,#REF!, $A14,#REF!, ">="&'Faturado mensal'!X$2,#REF!, "<"&EOMONTH('Faturado mensal'!X$2,0)) -> 0 | Y14: =SUMIFS(#REF!,#REF!, $A14,#REF!, ">="&'Faturado mensal'!M$2,#REF!, "<"&EOMONTH('Faturado mensal'!M$2,12)) -> 0 | Z14: =SUMIFS(#REF!,#REF!, $A14,#REF!, ">="&'Faturado mensal'!Z$2,#REF!, "<"&EOMONTH('Faturado mensal'!Z$2,0)) -> 0 | AA14: =SUMIFS(#REF!,#REF!, $A14,#REF!, ">="&'Faturado mensal'!AA$2,#REF!, "<"&EOMONTH('Faturado mensal'!AA$2,0)) -> 0 | AB14: =SUMIFS(#REF!,#REF!, $A14,#REF!, ">="&'Faturado mensal'!AB$2,#REF!, "<"&EOMONTH('Faturado mensal'!AB$2,0)) -> 0 | AC14: =SUMIFS(#REF!,#REF!, $A14,#REF!, ">="&'Faturado mensal'!AC$2,#REF!, "<"&EOMONTH('Faturado mensal'!AC$2,0)) -> 0 | AD14: =SUMIFS(#REF!,#REF!, $A14,#REF!, ">="&'Faturado mensal'!AD$2,#REF!, "<"&EOMONTH('Faturado mensal'!AD$2,0)) -> 0 | AE14: =SUMIFS(#REF!,#REF!, $A14,#REF!, ">="&'Faturado mensal'!AE$2,#REF!, "<"&EOMONTH('Faturado mensal'!AE$2,0)) -> 0 | AF14: =SUMIFS(#REF!,#REF!, $A14,#REF!, ">="&'Faturado mensal'!AF$2,#REF!, "<"&EOMONTH('Faturado mensal'!AF$2,0)) -> 0 | AG14: =SUMIFS(#REF!,#REF!, $A14,#REF!, ">="&'Faturado mensal'!AG$2,#REF!, "<"&EOMONTH('Faturado mensal'!AG$2,0)) -> 0 | ... AK14: =SUMIFS(#REF!,#REF!, $A14,#REF!, ">="&'Faturado mensal'!AK$2,#REF!, "<"&EOMONTH('Faturado mensal'!AK$2,0)) -> 0 | AL14: =SUMIFS(#REF!,#REF!, $A14,#REF!, ">="&Z$2,#REF!, "<"&EOMONTH(AK$2,0)) -> 0
A15: CS0000681 | B15: 070000685 | C15: AMPRO LABOR. E ENGa. S/C LTDA | D15: Ativo | E15: QSMA | F15: SERVIÇOS PRESTADOS | G15: INDUSTRIAL SRS | H15: B | I15: AMPRO LABOR. E ENGa. S/C LTDA | J15: 30 DIAS | K15: SRSFAB | L15: PRGM . COMPRAS - SRS - FABRICA | M15: =SUMIFS(#REF!,#REF!, $A15,#REF!, ">="&'Faturado mensal'!M$2,#REF!, "<"&EOMONTH('Faturado mensal'!M$2,0)) -> 0 | N15: =SUMIFS(#REF!,#REF!, $A15,#REF!, ">="&'Faturado mensal'!N$2,#REF!, "<"&EOMONTH('Faturado mensal'!N$2,0)) -> 0 | O15: =SUMIFS(#REF!,#REF!, $A15,#REF!, ">="&'Faturado mensal'!O$2,#REF!, "<"&EOMONTH('Faturado mensal'!O$2,0)) -> 1261 | P15: =SUMIFS(#REF!,#REF!, $A15,#REF!, ">="&'Faturado mensal'!P$2,#REF!, "<"&EOMONTH('Faturado mensal'!P$2,0)) -> 0 | Q15: =SUMIFS(#REF!,#REF!, $A15,#REF!, ">="&'Faturado mensal'!Q$2,#REF!, "<"&EOMONTH('Faturado mensal'!Q$2,0)) -> 0 | R15: =SUMIFS(#REF!,#REF!, $A15,#REF!, ">="&'Faturado mensal'!R$2,#REF!, "<"&EOMONTH('Faturado mensal'!R$2,0)) -> 1261 | S15: =SUMIFS(#REF!,#REF!, $A15,#REF!, ">="&'Faturado mensal'!S$2,#REF!, "<"&EOMONTH('Faturado mensal'!S$2,0)) -> 0 | T15: =SUMIFS(#REF!,#REF!, $A15,#REF!, ">="&'Faturado mensal'!T$2,#REF!, "<"&EOMONTH('Faturado mensal'!T$2,0)) -> 756 | ... X15: =SUMIFS(#REF!,#REF!, $A15,#REF!, ">="&'Faturado mensal'!X$2,#REF!, "<"&EOMONTH('Faturado mensal'!X$2,0)) -> 1305 | Y15: =SUMIFS(#REF!,#REF!, $A15,#REF!, ">="&'Faturado mensal'!M$2,#REF!, "<"&EOMONTH('Faturado mensal'!M$2,12)) -> 6148 | Z15: =SUMIFS(#REF!,#REF!, $A15,#REF!, ">="&'Faturado mensal'!Z$2,#REF!, "<"&EOMONTH('Faturado mensal'!Z$2,0)) -> 0 | AA15: =SUMIFS(#REF!,#REF!, $A15,#REF!, ">="&'Faturado mensal'!AA$2,#REF!, "<"&EOMONTH('Faturado mensal'!AA$2,0)) -> 0 | AB15: =SUMIFS(#REF!,#REF!, $A15,#REF!, ">="&'Faturado mensal'!AB$2,#REF!, "<"&EOMONTH('Faturado mensal'!AB$2,0)) -> 1305 | AC15: =SUMIFS(#REF!,#REF!, $A15,#REF!, ">="&'Faturado mensal'!AC$2,#REF!, "<"&EOMONTH('Faturado mensal'!AC$2,0)) -> 0 | AD15: =SUMIFS(#REF!,#REF!, $A15,#REF!, ">="&'Faturado mensal'!AD$2,#REF!, "<"&EOMONTH('Faturado mensal'!AD$2,0)) -> 0 | AE15: =SUMIFS(#REF!,#REF!, $A15,#REF!, ">="&'Faturado mensal'!AE$2,#REF!, "<"&EOMONTH('Faturado mensal'!AE$2,0)) -> 1305 | AF15: =SUMIFS(#REF!,#REF!, $A15,#REF!, ">="&'Faturado mensal'!AF$2,#REF!, "<"&EOMONTH('Faturado mensal'!AF$2,0)) -> 0 | AG15: =SUMIFS(#REF!,#REF!, $A15,#REF!, ">="&'Faturado mensal'!AG$2,#REF!, "<"&EOMONTH('Faturado mensal'!AG$2,0)) -> 0 | ... AK15: =SUMIFS(#REF!,#REF!, $A15,#REF!, ">="&'Faturado mensal'!AK$2,#REF!, "<"&EOMONTH('Faturado mensal'!AK$2,0)) -> 0 | AL15: =SUMIFS(#REF!,#REF!, $A15,#REF!, ">="&Z$2,#REF!, "<"&EOMONTH(AK$2,0)) -> 2610
A16: CS0000682 | B16: 090010126 | C16: H M CONSULTORIA LTDA | D16: Concluído | I16: H M CONSULTORIA LTDA | J16: 30 DIAS | K16: SRSFAB | L16: PRGM . COMPRAS - SRS - FABRICA | M16: =SUMIFS(#REF!,#REF!, $A16,#REF!, ">="&'Faturado mensal'!M$2,#REF!, "<"&EOMONTH('Faturado mensal'!M$2,0)) -> 0 | N16: =SUMIFS(#REF!,#REF!, $A16,#REF!, ">="&'Faturado mensal'!N$2,#REF!, "<"&EOMONTH('Faturado mensal'!N$2,0)) -> 0 | O16: =SUMIFS(#REF!,#REF!, $A16,#REF!, ">="&'Faturado mensal'!O$2,#REF!, "<"&EOMONTH('Faturado mensal'!O$2,0)) -> 0 | P16: =SUMIFS(#REF!,#REF!, $A16,#REF!, ">="&'Faturado mensal'!P$2,#REF!, "<"&EOMONTH('Faturado mensal'!P$2,0)) -> 0 | Q16: =SUMIFS(#REF!,#REF!, $A16,#REF!, ">="&'Faturado mensal'!Q$2,#REF!, "<"&EOMONTH('Faturado mensal'!Q$2,0)) -> 0 | R16: =SUMIFS(#REF!,#REF!, $A16,#REF!, ">="&'Faturado mensal'!R$2,#REF!, "<"&EOMONTH('Faturado mensal'!R$2,0)) -> 0 | S16: =SUMIFS(#REF!,#REF!, $A16,#REF!, ">="&'Faturado mensal'!S$2,#REF!, "<"&EOMONTH('Faturado mensal'!S$2,0)) -> 0 | T16: =SUMIFS(#REF!,#REF!, $A16,#REF!, ">="&'Faturado mensal'!T$2,#REF!, "<"&EOMONTH('Faturado mensal'!T$2,0)) -> 0 | ... X16: =SUMIFS(#REF!,#REF!, $A16,#REF!, ">="&'Faturado mensal'!X$2,#REF!, "<"&EOMONTH('Faturado mensal'!X$2,0)) -> 0 | Y16: =SUMIFS(#REF!,#REF!, $A16,#REF!, ">="&'Faturado mensal'!M$2,#REF!, "<"&EOMONTH('Faturado mensal'!M$2,12)) -> 0 | Z16: =SUMIFS(#REF!,#REF!, $A16,#REF!, ">="&'Faturado mensal'!Z$2,#REF!, "<"&EOMONTH('Faturado mensal'!Z$2,0)) -> 0 | AA16: =SUMIFS(#REF!,#REF!, $A16,#REF!, ">="&'Faturado mensal'!AA$2,#REF!, "<"&EOMONTH('Faturado mensal'!AA$2,0)) -> 0 | AB16: =SUMIFS(#REF!,#REF!, $A16,#REF!, ">="&'Faturado mensal'!AB$2,#REF!, "<"&EOMONTH('Faturado mensal'!AB$2,0)) -> 0 | AC16: =SUMIFS(#REF!,#REF!, $A16,#REF!, ">="&'Faturado mensal'!AC$2,#REF!, "<"&EOMONTH('Faturado mensal'!AC$2,0)) -> 0 | AD16: =SUMIFS(#REF!,#REF!, $A16,#REF!, ">="&'Faturado mensal'!AD$2,#REF!, "<"&EOMONTH('Faturado mensal'!AD$2,0)) -> 0 | AE16: =SUMIFS(#REF!,#REF!, $A16,#REF!, ">="&'Faturado mensal'!AE$2,#REF!, "<"&EOMONTH('Faturado mensal'!AE$2,0)) -> 0 | AF16: =SUMIFS(#REF!,#REF!, $A16,#REF!, ">="&'Faturado mensal'!AF$2,#REF!, "<"&EOMONTH('Faturado mensal'!AF$2,0)) -> 0 | AG16: =SUMIFS(#REF!,#REF!, $A16,#REF!, ">="&'Faturado mensal'!AG$2,#REF!, "<"&EOMONTH('Faturado mensal'!AG$2,0)) -> 0 | ... AK16: =SUMIFS(#REF!,#REF!, $A16,#REF!, ">="&'Faturado mensal'!AK$2,#REF!, "<"&EOMONTH('Faturado mensal'!AK$2,0)) -> 0 | AL16: =SUMIFS(#REF!,#REF!, $A16,#REF!, ">="&Z$2,#REF!, "<"&EOMONTH(AK$2,0)) -> 0
A17: CS0000683 | B17: 070076376 | C17: PAULO YOCHIKASU UEMATSU | D17: Concluído | G17: INDUSTRIAL SRS | H17: Indef | I17: PAULO YOCHIKASU UEMATSU | J17: 30 DIAS | K17: SRSFAB | L17: PRGM . COMPRAS - SRS - FABRICA | M17: =SUMIFS(#REF!,#REF!, $A17,#REF!, ">="&'Faturado mensal'!M$2,#REF!, "<"&EOMONTH('Faturado mensal'!M$2,0)) -> 0 | N17: =SUMIFS(#REF!,#REF!, $A17,#REF!, ">="&'Faturado mensal'!N$2,#REF!, "<"&EOMONTH('Faturado mensal'!N$2,0)) -> 0 | O17: =SUMIFS(#REF!,#REF!, $A17,#REF!, ">="&'Faturado mensal'!O$2,#REF!, "<"&EOMONTH('Faturado mensal'!O$2,0)) -> 0 | P17: =SUMIFS(#REF!,#REF!, $A17,#REF!, ">="&'Faturado mensal'!P$2,#REF!, "<"&EOMONTH('Faturado mensal'!P$2,0)) -> 0 | Q17: =SUMIFS(#REF!,#REF!, $A17,#REF!, ">="&'Faturado mensal'!Q$2,#REF!, "<"&EOMONTH('Faturado mensal'!Q$2,0)) -> 0 | R17: =SUMIFS(#REF!,#REF!, $A17,#REF!, ">="&'Faturado mensal'!R$2,#REF!, "<"&EOMONTH('Faturado mensal'!R$2,0)) -> 0 | S17: =SUMIFS(#REF!,#REF!, $A17,#REF!, ">="&'Faturado mensal'!S$2,#REF!, "<"&EOMONTH('Faturado mensal'!S$2,0)) -> 0 | T17: =SUMIFS(#REF!,#REF!, $A17,#REF!, ">="&'Faturado mensal'!T$2,#REF!, "<"&EOMONTH('Faturado mensal'!T$2,0)) -> 0 | ... X17: =SUMIFS(#REF!,#REF!, $A17,#REF!, ">="&'Faturado mensal'!X$2,#REF!, "<"&EOMONTH('Faturado mensal'!X$2,0)) -> 0 | Y17: =SUMIFS(#REF!,#REF!, $A17,#REF!, ">="&'Faturado mensal'!M$2,#REF!, "<"&EOMONTH('Faturado mensal'!M$2,12)) -> 0 | Z17: =SUMIFS(#REF!,#REF!, $A17,#REF!, ">="&'Faturado mensal'!Z$2,#REF!, "<"&EOMONTH('Faturado mensal'!Z$2,0)) -> 0 | AA17: =SUMIFS(#REF!,#REF!, $A17,#REF!, ">="&'Faturado mensal'!AA$2,#REF!, "<"&EOMONTH('Faturado mensal'!AA$2,0)) -> 0 | AB17: =SUMIFS(#REF!,#REF!, $A17,#REF!, ">="&'Faturado mensal'!AB$2,#REF!, "<"&EOMONTH('Faturado mensal'!AB$2,0)) -> 0 | AC17: =SUMIFS(#REF!,#REF!, $A17,#REF!, ">="&'Faturado mensal'!AC$2,#REF!, "<"&EOMONTH('Faturado mensal'!AC$2,0)) -> 0 | AD17: =SUMIFS(#REF!,#REF!, $A17,#REF!, ">="&'Faturado mensal'!AD$2,#REF!, "<"&EOMONTH('Faturado mensal'!AD$2,0)) -> 0 | AE17: =SUMIFS(#REF!,#REF!, $A17,#REF!, ">="&'Faturado mensal'!AE$2,#REF!, "<"&EOMONTH('Faturado mensal'!AE$2,0)) -> 0 | AF17: =SUMIFS(#REF!,#REF!, $A17,#REF!, ">="&'Faturado mensal'!AF$2,#REF!, "<"&EOMONTH('Faturado mensal'!AF$2,0)) -> 0 | AG17: =SUMIFS(#REF!,#REF!, $A17,#REF!, ">="&'Faturado mensal'!AG$2,#REF!, "<"&EOMONTH('Faturado mensal'!AG$2,0)) -> 0 | ... AK17: =SUMIFS(#REF!,#REF!, $A17,#REF!, ">="&'Faturado mensal'!AK$2,#REF!, "<"&EOMONTH('Faturado mensal'!AK$2,0)) -> 0 | AL17: =SUMIFS(#REF!,#REF!, $A17,#REF!, ">="&Z$2,#REF!, "<"&EOMONTH(AK$2,0)) -> 0
A18: CS0000685 | B18: 070075837 | C18: GS CONTROLE V. P. URBANAS LTDA | D18: Concluído | E18: QSMA | F18: MANUTENÇÃO EDIFÍCIOS / INSTALAÇÕES | G18: INDUSTRIAL VIES | H18: B | I18: GS CONTROLE V. P. URBANAS LTDA | J18: 30 DIAS | K18: VIESFB | L18: PRGM .COMPRAS - VIES - FABRICA | M18: =SUMIFS(#REF!,#REF!, $A18,#REF!, ">="&'Faturado mensal'!M$2,#REF!, "<"&EOMONTH('Faturado mensal'!M$2,0)) -> 0 | N18: =SUMIFS(#REF!,#REF!, $A18,#REF!, ">="&'Faturado mensal'!N$2,#REF!, "<"&EOMONTH('Faturado mensal'!N$2,0)) -> 0 | O18: =SUMIFS(#REF!,#REF!, $A18,#REF!, ">="&'Faturado mensal'!O$2,#REF!, "<"&EOMONTH('Faturado mensal'!O$2,0)) -> 0 | P18: =SUMIFS(#REF!,#REF!, $A18,#REF!, ">="&'Faturado mensal'!P$2,#REF!, "<"&EOMONTH('Faturado mensal'!P$2,0)) -> 0 | Q18: =SUMIFS(#REF!,#REF!, $A18,#REF!, ">="&'Faturado mensal'!Q$2,#REF!, "<"&EOMONTH('Faturado mensal'!Q$2,0)) -> 0 | R18: =SUMIFS(#REF!,#REF!, $A18,#REF!, ">="&'Faturado mensal'!R$2,#REF!, "<"&EOMONTH('Faturado mensal'!R$2,0)) -> 0 | S18: =SUMIFS(#REF!,#REF!, $A18,#REF!, ">="&'Faturado mensal'!S$2,#REF!, "<"&EOMONTH('Faturado mensal'!S$2,0)) -> 0 | T18: =SUMIFS(#REF!,#REF!, $A18,#REF!, ">="&'Faturado mensal'!T$2,#REF!, "<"&EOMONTH('Faturado mensal'!T$2,0)) -> 0 | ... X18: =SUMIFS(#REF!,#REF!, $A18,#REF!, ">="&'Faturado mensal'!X$2,#REF!, "<"&EOMONTH('Faturado mensal'!X$2,0)) -> 0 | Y18: =SUMIFS(#REF!,#REF!, $A18,#REF!, ">="&'Faturado mensal'!M$2,#REF!, "<"&EOMONTH('Faturado mensal'!M$2,12)) -> 0 | Z18: =SUMIFS(#REF!,#REF!, $A18,#REF!, ">="&'Faturado mensal'!Z$2,#REF!, "<"&EOMONTH('Faturado mensal'!Z$2,0)) -> 0 | AA18: =SUMIFS(#REF!,#REF!, $A18,#REF!, ">="&'Faturado mensal'!AA$2,#REF!, "<"&EOMONTH('Faturado mensal'!AA$2,0)) -> 0 | AB18: =SUMIFS(#REF!,#REF!, $A18,#REF!, ">="&'Faturado mensal'!AB$2,#REF!, "<"&EOMONTH('Faturado mensal'!AB$2,0)) -> 0 | AC18: =SUMIFS(#REF!,#REF!, $A18,#REF!, ">="&'Faturado mensal'!AC$2,#REF!, "<"&EOMONTH('Faturado mensal'!AC$2,0)) -> 0 | AD18: =SUMIFS(#REF!,#REF!, $A18,#REF!, ">="&'Faturado mensal'!AD$2,#REF!, "<"&EOMONTH('Faturado mensal'!AD$2,0)) -> 0 | AE18: =SUMIFS(#REF!,#REF!, $A18,#REF!, ">="&'Faturado mensal'!AE$2,#REF!, "<"&EOMONTH('Faturado mensal'!AE$2,0)) -> 0 | AF18: =SUMIFS(#REF!,#REF!, $A18,#REF!, ">="&'Faturado mensal'!AF$2,#REF!, "<"&EOMONTH('Faturado mensal'!AF$2,0)) -> 0 | AG18: =SUMIFS(#REF!,#REF!, $A18,#REF!, ">="&'Faturado mensal'!AG$2,#REF!, "<"&EOMONTH('Faturado mensal'!AG$2,0)) -> 0 | ... AK18: =SUMIFS(#REF!,#REF!, $A18,#REF!, ">="&'Faturado mensal'!AK$2,#REF!, "<"&EOMONTH('Faturado mensal'!AK$2,0)) -> 0 | AL18: =SUMIFS(#REF!,#REF!, $A18,#REF!, ">="&Z$2,#REF!, "<"&EOMONTH(AK$2,0)) -> 0
A19: CS0000686 | B19: 070075837 | C19: GS CONTROLE V. P. URBANAS LTDA | D19: Ativo | E19: QSMA | F19: MANUTENÇÃO EDIFÍCIOS / INSTALAÇÕES | G19: INDUSTRIAL VIES | H19: B | I19: GS CONTROLE V. P. URBANAS LTDA | J19: 30 DIAS | K19: VIESFB | L19: PRGM .COMPRAS - VIES - FABRICA | M19: =SUMIFS(#REF!,#REF!, $A19,#REF!, ">="&'Faturado mensal'!M$2,#REF!, "<"&EOMONTH('Faturado mensal'!M$2,0)) -> 283.62 | N19: =SUMIFS(#REF!,#REF!, $A19,#REF!, ">="&'Faturado mensal'!N$2,#REF!, "<"&EOMONTH('Faturado mensal'!N$2,0)) -> 0 | O19: =SUMIFS(#REF!,#REF!, $A19,#REF!, ">="&'Faturado mensal'!O$2,#REF!, "<"&EOMONTH('Faturado mensal'!O$2,0)) -> 0 | P19: =SUMIFS(#REF!,#REF!, $A19,#REF!, ">="&'Faturado mensal'!P$2,#REF!, "<"&EOMONTH('Faturado mensal'!P$2,0)) -> 283.62 | Q19: =SUMIFS(#REF!,#REF!, $A19,#REF!, ">="&'Faturado mensal'!Q$2,#REF!, "<"&EOMONTH('Faturado mensal'!Q$2,0)) -> 0 | R19: =SUMIFS(#REF!,#REF!, $A19,#REF!, ">="&'Faturado mensal'!R$2,#REF!, "<"&EOMONTH('Faturado mensal'!R$2,0)) -> 1828.63 | S19: =SUMIFS(#REF!,#REF!, $A19,#REF!, ">="&'Faturado mensal'!S$2,#REF!, "<"&EOMONTH('Faturado mensal'!S$2,0)) -> 1000 | T19: =SUMIFS(#REF!,#REF!, $A19,#REF!, ">="&'Faturado mensal'!T$2,#REF!, "<"&EOMONTH('Faturado mensal'!T$2,0)) -> 0 | ... X19: =SUMIFS(#REF!,#REF!, $A19,#REF!, ">="&'Faturado mensal'!X$2,#REF!, "<"&EOMONTH('Faturado mensal'!X$2,0)) -> 4458.63 | Y19: =SUMIFS(#REF!,#REF!, $A19,#REF!, ">="&'Faturado mensal'!M$2,#REF!, "<"&EOMONTH('Faturado mensal'!M$2,12)) -> 10169.5 | Z19: =SUMIFS(#REF!,#REF!, $A19,#REF!, ">="&'Faturado mensal'!Z$2,#REF!, "<"&EOMONTH('Faturado mensal'!Z$2,0)) -> 0 | AA19: =SUMIFS(#REF!,#REF!, $A19,#REF!, ">="&'Faturado mensal'!AA$2,#REF!, "<"&EOMONTH('Faturado mensal'!AA$2,0)) -> 2630 | AB19: =SUMIFS(#REF!,#REF!, $A19,#REF!, ">="&'Faturado mensal'!AB$2,#REF!, "<"&EOMONTH('Faturado mensal'!AB$2,0)) -> 1315 | AC19: =SUMIFS(#REF!,#REF!, $A19,#REF!, ">="&'Faturado mensal'!AC$2,#REF!, "<"&EOMONTH('Faturado mensal'!AC$2,0)) -> 0 | AD19: =SUMIFS(#REF!,#REF!, $A19,#REF!, ">="&'Faturado mensal'!AD$2,#REF!, "<"&EOMONTH('Faturado mensal'!AD$2,0)) -> 1315 | AE19: =SUMIFS(#REF!,#REF!, $A19,#REF!, ">="&'Faturado mensal'!AE$2,#REF!, "<"&EOMONTH('Faturado mensal'!AE$2,0)) -> 1315 | AF19: =SUMIFS(#REF!,#REF!, $A19,#REF!, ">="&'Faturado mensal'!AF$2,#REF!, "<"&EOMONTH('Faturado mensal'!AF$2,0)) -> 0 | AG19: =SUMIFS(#REF!,#REF!, $A19,#REF!, ">="&'Faturado mensal'!AG$2,#REF!, "<"&EOMONTH('Faturado mensal'!AG$2,0)) -> 0 | ... AK19: =SUMIFS(#REF!,#REF!, $A19,#REF!, ">="&'Faturado mensal'!AK$2,#REF!, "<"&EOMONTH('Faturado mensal'!AK$2,0)) -> 0 | AL19: =SUMIFS(#REF!,#REF!, $A19,#REF!, ">="&Z$2,#REF!, "<"&EOMONTH(AK$2,0)) -> 6575
A20: CS0000687 | B20: 070065603 | C20: TECMES E SERVICOS PRO INF LTDA | D20: Ativo | E20: ENGENHARIA PRODUTO | F20: SERVIÇOS PRESTADOS | G20: ENGENHARIA PRODUTO | H20: B | I20: TECMES E SERVICOS PRO INF LTDA | J20: 30 DIAS | K20: VIESFB | L20: PRGM .COMPRAS - VIES - FABRICA | M20: =SUMIFS(#REF!,#REF!, $A20,#REF!, ">="&'Faturado mensal'!M$2,#REF!, "<"&EOMONTH('Faturado mensal'!M$2,0)) -> 476.36 | N20: =SUMIFS(#REF!,#REF!, $A20,#REF!, ">="&'Faturado mensal'!N$2,#REF!, "<"&EOMONTH('Faturado mensal'!N$2,0)) -> 476.36 | O20: =SUMIFS(#REF!,#REF!, $A20,#REF!, ">="&'Faturado mensal'!O$2,#REF!, "<"&EOMONTH('Faturado mensal'!O$2,0)) -> 476.36 | P20: =SUMIFS(#REF!,#REF!, $A20,#REF!, ">="&'Faturado mensal'!P$2,#REF!, "<"&EOMONTH('Faturado mensal'!P$2,0)) -> 476.36 | Q20: =SUMIFS(#REF!,#REF!, $A20,#REF!, ">="&'Faturado mensal'!Q$2,#REF!, "<"&EOMONTH('Faturado mensal'!Q$2,0)) -> 476.36 | R20: =SUMIFS(#REF!,#REF!, $A20,#REF!, ">="&'Faturado mensal'!R$2,#REF!, "<"&EOMONTH('Faturado mensal'!R$2,0)) -> 476.36 | S20: =SUMIFS(#REF!,#REF!, $A20,#REF!, ">="&'Faturado mensal'!S$2,#REF!, "<"&EOMONTH('Faturado mensal'!S$2,0)) -> 476.36 | T20: =SUMIFS(#REF!,#REF!, $A20,#REF!, ">="&'Faturado mensal'!T$2,#REF!, "<"&EOMONTH('Faturado mensal'!T$2,0)) -> 476.36 | ... X20: =SUMIFS(#REF!,#REF!, $A20,#REF!, ">="&'Faturado mensal'!X$2,#REF!, "<"&EOMONTH('Faturado mensal'!X$2,0)) -> 476.36 | Y20: =SUMIFS(#REF!,#REF!, $A20,#REF!, ">="&'Faturado mensal'!M$2,#REF!, "<"&EOMONTH('Faturado mensal'!M$2,12)) -> 6192.68 | Z20: =SUMIFS(#REF!,#REF!, $A20,#REF!, ">="&'Faturado mensal'!Z$2,#REF!, "<"&EOMONTH('Faturado mensal'!Z$2,0)) -> 476.36 | AA20: =SUMIFS(#REF!,#REF!, $A20,#REF!, ">="&'Faturado mensal'!AA$2,#REF!, "<"&EOMONTH('Faturado mensal'!AA$2,0)) -> 476.36 | AB20: =SUMIFS(#REF!,#REF!, $A20,#REF!, ">="&'Faturado mensal'!AB$2,#REF!, "<"&EOMONTH('Faturado mensal'!AB$2,0)) -> 476.36 | AC20: =SUMIFS(#REF!,#REF!, $A20,#REF!, ">="&'Faturado mensal'!AC$2,#REF!, "<"&EOMONTH('Faturado mensal'!AC$2,0)) -> 476.36 | AD20: =SUMIFS(#REF!,#REF!, $A20,#REF!, ">="&'Faturado mensal'!AD$2,#REF!, "<"&EOMONTH('Faturado mensal'!AD$2,0)) -> 476.36 | AE20: =SUMIFS(#REF!,#REF!, $A20,#REF!, ">="&'Faturado mensal'!AE$2,#REF!, "<"&EOMONTH('Faturado mensal'!AE$2,0)) -> 476.36 | AF20: =SUMIFS(#REF!,#REF!, $A20,#REF!, ">="&'Faturado mensal'!AF$2,#REF!, "<"&EOMONTH('Faturado mensal'!AF$2,0)) -> 0 | AG20: =SUMIFS(#REF!,#REF!, $A20,#REF!, ">="&'Faturado mensal'!AG$2,#REF!, "<"&EOMONTH('Faturado mensal'!AG$2,0)) -> 0 | ... AK20: =SUMIFS(#REF!,#REF!, $A20,#REF!, ">="&'Faturado mensal'!AK$2,#REF!, "<"&EOMONTH('Faturado mensal'!AK$2,0)) -> 0 | AL20: =SUMIFS(#REF!,#REF!, $A20,#REF!, ">="&Z$2,#REF!, "<"&EOMONTH(AK$2,0)) -> 2858.16
A21: CS0000692 | B21: 070020209 | C21: AUDAX EXTINTORES COM.MAT.SEG.L | D21: Concluído | I21: AUDAX EXTINTORES COM.MAT.SEG.L | J21: 30 DIAS | K21: VIESFB | L21: PRGM .COMPRAS - VIES - FABRICA | M21: =SUMIFS(#REF!,#REF!, $A21,#REF!, ">="&'Faturado mensal'!M$2,#REF!, "<"&EOMONTH('Faturado mensal'!M$2,0)) -> 0 | N21: =SUMIFS(#REF!,#REF!, $A21,#REF!, ">="&'Faturado mensal'!N$2,#REF!, "<"&EOMONTH('Faturado mensal'!N$2,0)) -> 0 | O21: =SUMIFS(#REF!,#REF!, $A21,#REF!, ">="&'Faturado mensal'!O$2,#REF!, "<"&EOMONTH('Faturado mensal'!O$2,0)) -> 0 | P21: =SUMIFS(#REF!,#REF!, $A21,#REF!, ">="&'Faturado mensal'!P$2,#REF!, "<"&EOMONTH('Faturado mensal'!P$2,0)) -> 0 | Q21: =SUMIFS(#REF!,#REF!, $A21,#REF!, ">="&'Faturado mensal'!Q$2,#REF!, "<"&EOMONTH('Faturado mensal'!Q$2,0)) -> 0 | R21: =SUMIFS(#REF!,#REF!, $A21,#REF!, ">="&'Faturado mensal'!R$2,#REF!, "<"&EOMONTH('Faturado mensal'!R$2,0)) -> 0 | S21: =SUMIFS(#REF!,#REF!, $A21,#REF!, ">="&'Faturado mensal'!S$2,#REF!, "<"&EOMONTH('Faturado mensal'!S$2,0)) -> 0 | T21: =SUMIFS(#REF!,#REF!, $A21,#REF!, ">="&'Faturado mensal'!T$2,#REF!, "<"&EOMONTH('Faturado mensal'!T$2,0)) -> 0 | ... X21: =SUMIFS(#REF!,#REF!, $A21,#REF!, ">="&'Faturado mensal'!X$2,#REF!, "<"&EOMONTH('Faturado mensal'!X$2,0)) -> 0 | Y21: =SUMIFS(#REF!,#REF!, $A21,#REF!, ">="&'Faturado mensal'!M$2,#REF!, "<"&EOMONTH('Faturado mensal'!M$2,12)) -> 0 | Z21: =SUMIFS(#REF!,#REF!, $A21,#REF!, ">="&'Faturado mensal'!Z$2,#REF!, "<"&EOMONTH('Faturado mensal'!Z$2,0)) -> 0 | AA21: =SUMIFS(#REF!,#REF!, $A21,#REF!, ">="&'Faturado mensal'!AA$2,#REF!, "<"&EOMONTH('Faturado mensal'!AA$2,0)) -> 0 | AB21: =SUMIFS(#REF!,#REF!, $A21,#REF!, ">="&'Faturado mensal'!AB$2,#REF!, "<"&EOMONTH('Faturado mensal'!AB$2,0)) -> 0 | AC21: =SUMIFS(#REF!,#REF!, $A21,#REF!, ">="&'Faturado mensal'!AC$2,#REF!, "<"&EOMONTH('Faturado mensal'!AC$2,0)) -> 0 | AD21: =SUMIFS(#REF!,#REF!, $A21,#REF!, ">="&'Faturado mensal'!AD$2,#REF!, "<"&EOMONTH('Faturado mensal'!AD$2,0)) -> 0 | AE21: =SUMIFS(#REF!,#REF!, $A21,#REF!, ">="&'Faturado mensal'!AE$2,#REF!, "<"&EOMONTH('Faturado mensal'!AE$2,0)) -> 0 | AF21: =SUMIFS(#REF!,#REF!, $A21,#REF!, ">="&'Faturado mensal'!AF$2,#REF!, "<"&EOMONTH('Faturado mensal'!AF$2,0)) -> 0 | AG21: =SUMIFS(#REF!,#REF!, $A21,#REF!, ">="&'Faturado mensal'!AG$2,#REF!, "<"&EOMONTH('Faturado mensal'!AG$2,0)) -> 0 | ... AK21: =SUMIFS(#REF!,#REF!, $A21,#REF!, ">="&'Faturado mensal'!AK$2,#REF!, "<"&EOMONTH('Faturado mensal'!AK$2,0)) -> 0 | AL21: =SUMIFS(#REF!,#REF!, $A21,#REF!, ">="&Z$2,#REF!, "<"&EOMONTH(AK$2,0)) -> 0
A22: CS0000693 | B22: 090010056 | C22: VERZANI & SANDRINI ADM.MO LTDA | D22: Concluído | I22: VERZANI & SANDRINI ADM.MO LTDA | J22: 30 DIAS | K22: VIESFB | L22: PRGM .COMPRAS - VIES - FABRICA | M22: =SUMIFS(#REF!,#REF!, $A22,#REF!, ">="&'Faturado mensal'!M$2,#REF!, "<"&EOMONTH('Faturado mensal'!M$2,0)) -> 0 | N22: =SUMIFS(#REF!,#REF!, $A22,#REF!, ">="&'Faturado mensal'!N$2,#REF!, "<"&EOMONTH('Faturado mensal'!N$2,0)) -> 0 | O22: =SUMIFS(#REF!,#REF!, $A22,#REF!, ">="&'Faturado mensal'!O$2,#REF!, "<"&EOMONTH('Faturado mensal'!O$2,0)) -> 0 | P22: =SUMIFS(#REF!,#REF!, $A22,#REF!, ">="&'Faturado mensal'!P$2,#REF!, "<"&EOMONTH('Faturado mensal'!P$2,0)) -> 0 | Q22: =SUMIFS(#REF!,#REF!, $A22,#REF!, ">="&'Faturado mensal'!Q$2,#REF!, "<"&EOMONTH('Faturado mensal'!Q$2,0)) -> 0 | R22: =SUMIFS(#REF!,#REF!, $A22,#REF!, ">="&'Faturado mensal'!R$2,#REF!, "<"&EOMONTH('Faturado mensal'!R$2,0)) -> 0 | S22: =SUMIFS(#REF!,#REF!, $A22,#REF!, ">="&'Faturado mensal'!S$2,#REF!, "<"&EOMONTH('Faturado mensal'!S$2,0)) -> 0 | T22: =SUMIFS(#REF!,#REF!, $A22,#REF!, ">="&'Faturado mensal'!T$2,#REF!, "<"&EOMONTH('Faturado mensal'!T$2,0)) -> 0 | ... X22: =SUMIFS(#REF!,#REF!, $A22,#REF!, ">="&'Faturado mensal'!X$2,#REF!, "<"&EOMONTH('Faturado mensal'!X$2,0)) -> 0 | Y22: =SUMIFS(#REF!,#REF!, $A22,#REF!, ">="&'Faturado mensal'!M$2,#REF!, "<"&EOMONTH('Faturado mensal'!M$2,12)) -> 0 | Z22: =SUMIFS(#REF!,#REF!, $A22,#REF!, ">="&'Faturado mensal'!Z$2,#REF!, "<"&EOMONTH('Faturado mensal'!Z$2,0)) -> 0 | AA22: =SUMIFS(#REF!,#REF!, $A22,#REF!, ">="&'Faturado mensal'!AA$2,#REF!, "<"&EOMONTH('Faturado mensal'!AA$2,0)) -> 0 | AB22: =SUMIFS(#REF!,#REF!, $A22,#REF!, ">="&'Faturado mensal'!AB$2,#REF!, "<"&EOMONTH('Faturado mensal'!AB$2,0)) -> 0 | AC22: =SUMIFS(#REF!,#REF!, $A22,#REF!, ">="&'Faturado mensal'!AC$2,#REF!, "<"&EOMONTH('Faturado mensal'!AC$2,0)) -> 0 | AD22: =SUMIFS(#REF!,#REF!, $A22,#REF!, ">="&'Faturado mensal'!AD$2,#REF!, "<"&EOMONTH('Faturado mensal'!AD$2,0)) -> 0 | AE22: =SUMIFS(#REF!,#REF!, $A22,#REF!, ">="&'Faturado mensal'!AE$2,#REF!, "<"&EOMONTH('Faturado mensal'!AE$2,0)) -> 0 | AF22: =SUMIFS(#REF!,#REF!, $A22,#REF!, ">="&'Faturado mensal'!AF$2,#REF!, "<"&EOMONTH('Faturado mensal'!AF$2,0)) -> 0 | AG22: =SUMIFS(#REF!,#REF!, $A22,#REF!, ">="&'Faturado mensal'!AG$2,#REF!, "<"&EOMONTH('Faturado mensal'!AG$2,0)) -> 0 | ... AK22: =SUMIFS(#REF!,#REF!, $A22,#REF!, ">="&'Faturado mensal'!AK$2,#REF!, "<"&EOMONTH('Faturado mensal'!AK$2,0)) -> 0 | AL22: =SUMIFS(#REF!,#REF!, $A22,#REF!, ">="&Z$2,#REF!, "<"&EOMONTH(AK$2,0)) -> 0
A23: CS0000696 | B23: 090003565 | C23: IMIGRANTES EMPREEND. PART.LTDA | D23: Ativo | E23: CONSELHO | F23: SERVIÇOS PRESTADOS | G23: ADMINISTRATIVO | H23: C | I23: IMIGRANTES EMPREEND. PART.LTDA | J23: 30 DIAS | K23: 333ADM | L23: COMPRAS - 333 - ADMINISTRAÇÃO | M23: =SUMIFS(#REF!,#REF!, $A23,#REF!, ">="&'Faturado mensal'!M$2,#REF!, "<"&EOMONTH('Faturado mensal'!M$2,0)) -> 81089.2 | N23: =SUMIFS(#REF!,#REF!, $A23,#REF!, ">="&'Faturado mensal'!N$2,#REF!, "<"&EOMONTH('Faturado mensal'!N$2,0)) -> 81786.34 | O23: =SUMIFS(#REF!,#REF!, $A23,#REF!, ">="&'Faturado mensal'!O$2,#REF!, "<"&EOMONTH('Faturado mensal'!O$2,0)) -> 79690.48 | P23: =SUMIFS(#REF!,#REF!, $A23,#REF!, ">="&'Faturado mensal'!P$2,#REF!, "<"&EOMONTH('Faturado mensal'!P$2,0)) -> 91130.89 | Q23: =SUMIFS(#REF!,#REF!, $A23,#REF!, ">="&'Faturado mensal'!Q$2,#REF!, "<"&EOMONTH('Faturado mensal'!Q$2,0)) -> 83578.77 | R23: =SUMIFS(#REF!,#REF!, $A23,#REF!, ">="&'Faturado mensal'!R$2,#REF!, "<"&EOMONTH('Faturado mensal'!R$2,0)) -> 82283.88 | S23: =SUMIFS(#REF!,#REF!, $A23,#REF!, ">="&'Faturado mensal'!S$2,#REF!, "<"&EOMONTH('Faturado mensal'!S$2,0)) -> 78146.75 | T23: =SUMIFS(#REF!,#REF!, $A23,#REF!, ">="&'Faturado mensal'!T$2,#REF!, "<"&EOMONTH('Faturado mensal'!T$2,0)) -> 93690.94 | ... X23: =SUMIFS(#REF!,#REF!, $A23,#REF!, ">="&'Faturado mensal'!X$2,#REF!, "<"&EOMONTH('Faturado mensal'!X$2,0)) -> 125650.73 | Y23: =SUMIFS(#REF!,#REF!, $A23,#REF!, ">="&'Faturado mensal'!M$2,#REF!, "<"&EOMONTH('Faturado mensal'!M$2,12)) -> 1234291.7 | Z23: =SUMIFS(#REF!,#REF!, $A23,#REF!, ">="&'Faturado mensal'!Z$2,#REF!, "<"&EOMONTH('Faturado mensal'!Z$2,0)) -> 146093.96 | AA23: =SUMIFS(#REF!,#REF!, $A23,#REF!, ">="&'Faturado mensal'!AA$2,#REF!, "<"&EOMONTH('Faturado mensal'!AA$2,0)) -> 77365.62 | AB23: =SUMIFS(#REF!,#REF!, $A23,#REF!, ">="&'Faturado mensal'!AB$2,#REF!, "<"&EOMONTH('Faturado mensal'!AB$2,0)) -> 126650.56 | AC23: =SUMIFS(#REF!,#REF!, $A23,#REF!, ">="&'Faturado mensal'!AC$2,#REF!, "<"&EOMONTH('Faturado mensal'!AC$2,0)) -> 145954.6 | AD23: =SUMIFS(#REF!,#REF!, $A23,#REF!, ">="&'Faturado mensal'!AD$2,#REF!, "<"&EOMONTH('Faturado mensal'!AD$2,0)) -> 121054.8 | AE23: =SUMIFS(#REF!,#REF!, $A23,#REF!, ">="&'Faturado mensal'!AE$2,#REF!, "<"&EOMONTH('Faturado mensal'!AE$2,0)) -> 104715.95 | AF23: =SUMIFS(#REF!,#REF!, $A23,#REF!, ">="&'Faturado mensal'!AF$2,#REF!, "<"&EOMONTH('Faturado mensal'!AF$2,0)) -> 0 | AG23: =SUMIFS(#REF!,#REF!, $A23,#REF!, ">="&'Faturado mensal'!AG$2,#REF!, "<"&EOMONTH('Faturado mensal'!AG$2,0)) -> 0 | ... AK23: =SUMIFS(#REF!,#REF!, $A23,#REF!, ">="&'Faturado mensal'!AK$2,#REF!, "<"&EOMONTH('Faturado mensal'!AK$2,0)) -> 0 | AL23: =SUMIFS(#REF!,#REF!, $A23,#REF!, ">="&Z$2,#REF!, "<"&EOMONTH(AK$2,0)) -> 724763.49
A24: CS0000698 | B24: 070001585 | C24: TELOS CONSULTORIA EMPRESARIAL LTDA | D24: Concluído | I24: TELOS CONSULTORIA EMPRESARIAL | J24: 30 DIAS | K24: COFAB | L24: PRGM . COMPRAS - CO - FABRICA | M24: =SUMIFS(#REF!,#REF!, $A24,#REF!, ">="&'Faturado mensal'!M$2,#REF!, "<"&EOMONTH('Faturado mensal'!M$2,0)) -> 0 | N24: =SUMIFS(#REF!,#REF!, $A24,#REF!, ">="&'Faturado mensal'!N$2,#REF!, "<"&EOMONTH('Faturado mensal'!N$2,0)) -> 0 | O24: =SUMIFS(#REF!,#REF!, $A24,#REF!, ">="&'Faturado mensal'!O$2,#REF!, "<"&EOMONTH('Faturado mensal'!O$2,0)) -> 0 | P24: =SUMIFS(#REF!,#REF!, $A24,#REF!, ">="&'Faturado mensal'!P$2,#REF!, "<"&EOMONTH('Faturado mensal'!P$2,0)) -> 0 | Q24: =SUMIFS(#REF!,#REF!, $A24,#REF!, ">="&'Faturado mensal'!Q$2,#REF!, "<"&EOMONTH('Faturado mensal'!Q$2,0)) -> 0 | R24: =SUMIFS(#REF!,#REF!, $A24,#REF!, ">="&'Faturado mensal'!R$2,#REF!, "<"&EOMONTH('Faturado mensal'!R$2,0)) -> 0 | S24: =SUMIFS(#REF!,#REF!, $A24,#REF!, ">="&'Faturado mensal'!S$2,#REF!, "<"&EOMONTH('Faturado mensal'!S$2,0)) -> 0 | T24: =SUMIFS(#REF!,#REF!, $A24,#REF!, ">="&'Faturado mensal'!T$2,#REF!, "<"&EOMONTH('Faturado mensal'!T$2,0)) -> 0 | ... X24: =SUMIFS(#REF!,#REF!, $A24,#REF!, ">="&'Faturado mensal'!X$2,#REF!, "<"&EOMONTH('Faturado mensal'!X$2,0)) -> 0 | Y24: =SUMIFS(#REF!,#REF!, $A24,#REF!, ">="&'Faturado mensal'!M$2,#REF!, "<"&EOMONTH('Faturado mensal'!M$2,12)) -> 0 | Z24: =SUMIFS(#REF!,#REF!, $A24,#REF!, ">="&'Faturado mensal'!Z$2,#REF!, "<"&EOMONTH('Faturado mensal'!Z$2,0)) -> 0 | AA24: =SUMIFS(#REF!,#REF!, $A24,#REF!, ">="&'Faturado mensal'!AA$2,#REF!, "<"&EOMONTH('Faturado mensal'!AA$2,0)) -> 0 | AB24: =SUMIFS(#REF!,#REF!, $A24,#REF!, ">="&'Faturado mensal'!AB$2,#REF!, "<"&EOMONTH('Faturado mensal'!AB$2,0)) -> 0 | AC24: =SUMIFS(#REF!,#REF!, $A24,#REF!, ">="&'Faturado mensal'!AC$2,#REF!, "<"&EOMONTH('Faturado mensal'!AC$2,0)) -> 0 | AD24: =SUMIFS(#REF!,#REF!, $A24,#REF!, ">="&'Faturado mensal'!AD$2,#REF!, "<"&EOMONTH('Faturado mensal'!AD$2,0)) -> 0 | AE24: =SUMIFS(#REF!,#REF!, $A24,#REF!, ">="&'Faturado mensal'!AE$2,#REF!, "<"&EOMONTH('Faturado mensal'!AE$2,0)) -> 0 | AF24: =SUMIFS(#REF!,#REF!, $A24,#REF!, ">="&'Faturado mensal'!AF$2,#REF!, "<"&EOMONTH('Faturado mensal'!AF$2,0)) -> 0 | AG24: =SUMIFS(#REF!,#REF!, $A24,#REF!, ">="&'Faturado mensal'!AG$2,#REF!, "<"&EOMONTH('Faturado mensal'!AG$2,0)) -> 0 | ... AK24: =SUMIFS(#REF!,#REF!, $A24,#REF!, ">="&'Faturado mensal'!AK$2,#REF!, "<"&EOMONTH('Faturado mensal'!AK$2,0)) -> 0 | AL24: =SUMIFS(#REF!,#REF!, $A24,#REF!, ">="&Z$2,#REF!, "<"&EOMONTH(AK$2,0)) -> 0
